Workbook

Sheet 追加新規商品コード
A1: 追加新規商品コード（自動検出／人確認用）
A2: 商品コード | B2: 商品名 | C2: 在庫数 | D2: 移動先シート | E2: 初回検知日 | F2: 状態 | G2: SourceType | H2: SourceLabel
A3: 0500FG | B3: 500FGﾚｲｺｰ燃料ﾌｨﾙﾀｰｾｯﾄ品 | C3: 0 | D3: 1 | E3: 46293 | F3: 未振分 | G3: Sub | H3: 倉庫在庫データ.csv
A4: 0900FH | B4: 0900FHﾚｲｺｰ燃料ﾌｨﾙﾀｰｾｯﾄ品 | C4: 20 | D4: 1 | E4: 46293 | F4: 未振分 | G4: Sub | H4: 倉庫在庫データ.csv
A5: 1000FH | B5: 1000FHﾚｲｺｰ燃料ﾌｨﾙﾀｰｾｯﾄ品 | C5: 0 | D5: 1 | E5: 46293 | F5: 未振分 | G5: Sub | H5: 倉庫在庫データ.csv
A6: 1FB33005 | B6: BCS180*120給水Wｽﾀﾝ後部用筒のみ | C6: 5 | D6: 3 | E6: 46293 | F6: 未振分 | G6: Sub | H6: 倉庫在庫データ.csv
A7: 1FB33006 | B7: BCS180*120前金具給水 | C7: 6 | D7: 3 | E7: 46293 | F7: 未振分 | G7: Sub | H7: 倉庫在庫データ.csv
A8: 1FB33007 | B8: BCS180*115前金具給水 | C8: 1 | D8: 3 | E8: 46293 | F8: 未振分 | G8: Sub | H8: 倉庫在庫データ.csv
A9: 1FB33008 | B9: BCS180*115後金具給水 | C9: 1 | D9: 3 | E9: 46293 | F9: 未振分 | G9: Sub | H9: 倉庫在庫データ.csv
A10: 1FC53002 | B10: BCS170*20TWｽﾀﾝ用丸座金 | C10: 4 | D10: 3 | E10: 46293 | F10: 未振分 | G10: Sub | H10: 倉庫在庫データ.csv
A11: 1FC54002 | B11: BCS77*42ﾊﾟｯｷﾝｸﾞﾗﾝﾄﾞ | C11: 77 | D11: 3 | E11: 46293 | F11: 未振分 | G11: Sub | H11: 倉庫在庫データ.csv
A12: 1FC54003 | B12: BCS96*48ﾊﾟｯｷﾝｸﾞﾗﾝﾄﾞ | C12: 7 | D12: 3 | E12: 46293 | F12: 未振分 | G12: Sub | H12: 倉庫在庫データ.csv
A13: 1FC54004 | B13: BCS110*55ﾊﾟｯｷﾝｸﾞﾗﾝﾄﾞ | C13: 18 | D13: 3 | E13: 46293 | F13: 未振分 | G13: Sub | H13: 倉庫在庫データ.csv
A14: 1FC54005 | B14: BCS120*65ﾊﾟｯｷﾝｸﾞﾗﾝﾄﾞ | C14: 11 | D14: 3 | E14: 46293 | F14: 未振分 | G14: Sub | H14: 倉庫在庫データ.csv
... A26: 50SPFNASI | B26: 50SPﾌﾗﾝｼﾞ型海水こし器(ﾌﾗﾝｼﾞ無し) | C26: 15 | D26: 6 | E26: 46293 | F26: 未振分 | G26: Sub | H26: 倉庫在庫データ.csv
A27: 6KR04M | B27: 4M6角ﾚﾝﾁ | C27: 207 | E27: 46293 | F27: 未振分 | G27: Sub | H27: 倉庫在庫データ.csv
A28: 6KR05M | B28: 5M6角ﾚﾝﾁ | C28: 243 | E28: 46293 | F28: 未振分 | G28: Sub | H28: 倉庫在庫データ.csv
A29: 6KR10M | B29: 10M6角ﾚﾝﾁ | C29: 77 | E29: 46293 | F29: 未振分 | G29: Sub | H29: 倉庫在庫データ.csv
A30: 6KR14M | B30: 14M6角ﾚﾝﾁ | C30: 78 | E30: 46293 | F30: 未振分 | G30: Sub | H30: 倉庫在庫データ.csv
A31: 8808454 | B31: 8808454亜鉛棒(ﾌﾟﾗｸﾞ付)21φｘ50ｘ77 | C31: 0 | E31: 46293 | F31: 未振分 | G31: Sub | H31: 倉庫在庫データ.csv
A32: A070R | B32: A-70ｱﾙﾐｶﾞｲﾄﾞﾛｰﾗｰ用ﾛｰﾗｰ | C32: 71 | E32: 46293 | F32: 未振分 | G32: Sub | H32: 倉庫在庫データ.csv
A33: A090 | B33: A-90ｱﾙﾐｶﾞｲﾄﾞﾛｰﾗｰ | C33: 6 | E33: 46293 | F33: 未振分 | G33: Sub | H33: 倉庫在庫データ.csv
A34: A090R | B34: A-90ｱﾙﾐｶﾞｲﾄﾞﾛｰﾗｰ用ﾛｰﾗｰ | C34: 18 | E34: 46293 | F34: 未振分 | G34: Sub | H34: 倉庫在庫データ.csv
A35: A140R | B35: A-140ｱﾙﾐｶﾞｲﾄﾞﾛｰﾗｰ用ﾛｰﾗｰ | C35: 34 | E35: 46293 | F35: 未振分 | G35: Sub | H35: 倉庫在庫データ.csv
A36: A2K09 | B36: BS3/8ｴｱｰ2方ｺｯｸ | C36: 3 | E36: 46293 | F36: 未振分 | G36: Sub | H36: 倉庫在庫データ.csv
A37: A31509 | B37: A31509日発用ｸﾗﾝﾌﾟ | C37: 57 | E37: 46293 | F37: 未振分 | G37: Sub | H37: 倉庫在庫データ.csv
A38: A31538 | B38: A31538日発用ｼﾑ | C38: 62 | E38: 46293 | F38: 未振分 | G38: Sub | H38: 倉庫在庫データ.csv
... A6047: ZZZ045 | B6047: ZZZ製45軸受ﾒﾀﾙ | C6047: 2 | E6047: 46293 | F6047: 未振分 | G6047: Sub | H6047: 倉庫在庫データ.csv

Sheet 欠品
B41: 46252 | C41: 46253 | D41: 46254 | E41: 46255 | F41: 46258 | G41: 46259 | H41: 46260 | I41: 46261 | J41: 46262 | K41: 46265 | L41: 46266 | M41: 46267 | N41: 46268 | O41: 46269 | P41: 46272 | Q41: 46273 | R41: 46274 | S41: 46275 | T41: 46276 | U41: 46279 | V41: 46280 | W41: 46281 | X41: 46282 | Y41: 46283 | Z41: 46289 | AA41: 46290 | AB41: 46293 | AC41: =TODAY() -> 46293
A42: 目標 | B42: =(MAX($B43:$AE43)+MIN($B43:$AE43))/2 -> 11 | C42: =(MAX($B43:$AE43)+MIN($B43:$AE43))/2 -> 11 | D42: =(MAX($B43:$AE43)+MIN($B43:$AE43))/2 -> 11 | E42: =(MAX($B43:$AE43)+MIN($B43:$AE43))/2 -> 11 | F42: =(MAX($B43:$AE43)+MIN($B43:$AE43))/2 -> 11 | G42: =(MAX($B43:$AE43)+MIN($B43:$AE43))/2 -> 11 | H42: =(MAX($B43:$AE43)+MIN($B43:$AE43))/2 -> 11 | I42: =(MAX($B43:$AE43)+MIN($B43:$AE43))/2 -> 11 | ... AC42: =(MAX($B43:$AE43)+MIN($B43:$AE43))/2 -> 11 | AD42: 0.035
A43: 合計 | B43: =SUM(B44:B61) -> 9 | C43: =SUM(C44:C61) -> 9 | D43: =SUM(D44:D61) -> 12 | E43: =SUM(E44:E61) -> 13 | F43: =SUM(F44:F61) -> 17 | G43: =SUM(G44:G61) -> 13 | H43: =SUM(H44:H61) -> 14 | I43: =SUM(I44:I61) -> 14 | ... AC43: =SUM(AC44:AC61) -> 6
A44: ='1'!$C$2 -> 1.その他 | B44: 0 | C44: 0 | D44: 0 | E44: 0 | F44: 0 | G44: 0 | H44: 0 | I44: 0 | J44: 0 | K44: 0 | L44: 0 | M44: 0 | N44: 0 | O44: 0 | P44: 0 | Q44: 0 | R44: 0 | S44: 0 | T44: 0 | U44: 0 | V44: 0 | W44: 0 | X44: 0 | Y44: 0 | Z44: 0 | AA44: 0 | AB44: 0 | AC44: ='1'!I2 -> 0
A45: ='10'!C2 -> 10.ミキシング | B45: 0 | C45: 0 | D45: 0 | E45: 0 | F45: 0 | G45: 0 | H45: 0 | I45: 0 | J45: 0 | K45: 0 | L45: 0 | M45: 0 | N45: 0 | O45: 0 | P45: 0 | Q45: 0 | R45: 0 | S45: 0 | T45: 0 | U45: 1 | V45: 1 | W45: 1 | X45: 1 | Y45: 1 | Z45: 1 | AA45: 1 | AB45: 1 | AC45: ='10'!I2 -> 1
A46: ='11'!C2 -> 11.シール類 | B46: 1 | C46: 1 | D46: 1 | E46: 1 | F46: 1 | G46: 1 | H46: 1 | I46: 1 | J46: 1 | K46: 1 | L46: 1 | M46: 1 | N46: 1 | O46: 1 | P46: 1 | Q46: 1 | R46: 1 | S46: 1 | T46: 1 | U46: 1 | V46: 1 | W46: 1 | X46: 1 | Y46: 1 | Z46: 1 | AA46: 1 | AB46: 1 | AC46: ='11'!I2 -> 1
A47: ='12'!C2 -> 12.バルブ類 | B47: 1 | C47: 1 | D47: 1 | E47: 1 | F47: 1 | G47: 1 | H47: 1 | I47: 1 | J47: 1 | K47: 1 | L47: 1 | M47: 1 | N47: 1 | O47: 1 | P47: 1 | Q47: 1 | R47: 1 | S47: 1 | T47: 1 | U47: 0 | V47: 0 | W47: 0 | X47: 0 | Y47: 0 | Z47: 0 | AA47: 0 | AB47: 0 | AC47: ='12'!I2 -> 0
A48: ='13'!$C$2 -> 13.亜鉛棒 | B48: 0 | C48: 0 | D48: 0 | E48: 0 | F48: 0 | G48: 0 | H48: 0 | I48: 0 | J48: 0 | K48: 0 | L48: 0 | M48: 0 | N48: 0 | O48: 0 | P48: 0 | Q48: 0 | R48: 0 | S48: 0 | T48: 0 | U48: 0 | V48: 0 | W48: 0 | X48: 0 | Y48: 0 | Z48: 0 | AA48: 0 | AB48: 0 | AC48: ='13'!I2 -> 0
A49: ='14'!C2 -> 14.メタル | B49: 1 | C49: 1 | D49: 1 | E49: 1 | F49: 1 | G49: 1 | H49: 1 | I49: 1 | J49: 1 | K49: 1 | L49: 1 | M49: 1 | N49: 1 | O49: 1 | P49: 1 | Q49: 1 | R49: 1 | S49: 1 | T49: 1 | U49: 1 | V49: 1 | W49: 1 | X49: 1 | Y49: 1 | Z49: 1 | AA49: 1 | AB49: 1 | AC49: ='14'!I2 -> 1
A50: ='15'!$C$2 -> 15.ポンプ | B50: 0 | C50: 0 | D50: 0 | E50: 0 | F50: 0 | G50: 0 | H50: 0 | I50: 0 | J50: 0 | K50: 0 | L50: 0 | M50: 0 | N50: 0 | O50: 0 | P50: 0 | Q50: 0 | R50: 0 | S50: 0 | T50: 0 | U50: 0 | V50: 0 | W50: 0 | X50: 0 | Y50: 0 | Z50: 0 | AA50: 0 | AB50: 0 | AC50: ='15'!I2 -> 0
A51: ='16'!$C$2 -> 16.ペラ亜鉛 | B51: 3 | C51: 3 | D51: 5 | E51: 5 | F51: 6 | G51: 4 | H51: 4 | I51: 5 | J51: 5 | K51: 5 | L51: 3 | M51: 2 | N51: 2 | O51: 2 | P51: 2 | Q51: 2 | R51: 2 | S51: 2 | T51: 2 | U51: 2 | V51: 1 | W51: 1 | X51: 1 | Y51: 1 | Z51: 1 | AA51: 1 | AB51: 1 | AC51: ='16'!I2 -> 1
A52: ='17'!C2 -> 17.亜鉛板 | B52: 0 | C52: 0 | D52: 0 | E52: 0 | F52: 0 | G52: 0 | H52: 0 | I52: 0 | J52: 0 | K52: 0 | L52: 0 | M52: 0 | N52: 0 | O52: 0 | P52: 0 | Q52: 0 | R52: 0 | S52: 0 | T52: 0 | U52: 0 | V52: 0 | W52: 0 | X52: 0 | Y52: 0 | Z52: 0 | AA52: 0 | AB52: 0 | AC52: ='17'!I2 -> 0
A53: ='18'!$C$2 -> 18.ドラム | B53: 0 | C53: 0 | D53: 0 | E53: 0 | F53: 0 | G53: 0 | H53: 0 | I53: 0 | J53: 0 | K53: 0 | L53: 0 | M53: 0 | N53: 0 | O53: 0 | P53: 0 | Q53: 0 | R53: 0 | S53: 0 | T53: 0 | U53: 0 | V53: 0 | W53: 0 | X53: 0 | Y53: 0 | Z53: 0 | AA53: 0 | AB53: 0 | AC53: ='18'!I2 -> 0
A54: ='2'!C2 -> 2.ﾕﾆﾊﾞｰｻﾙ | B54: 1 | C54: 1 | D54: 1 | E54: 2 | F54: 2 | G54: 0 | H54: 0 | I54: 0 | J54: 0 | K54: 0 | L54: 0 | M54: 0 | N54: 0 | O54: 0 | P54: 0 | Q54: 0 | R54: 0 | S54: 0 | T54: 0 | U54: 0 | V54: 0 | W54: 0 | X54: 0 | Y54: 0 | Z54: 0 | AA54: 0 | AB54: 0 | AC54: ='2'!I2 -> 0
A55: ='3'!C2 -> 3.スタン | B55: 1 | C55: 1 | D55: 2 | E55: 2 | F55: 3 | G55: 3 | H55: 3 | I55: 2 | J55: 2 | K55: 2 | L55: 1 | M55: 1 | N55: 1 | O55: 1 | P55: 0 | Q55: 0 | R55: 0 | S55: 0 | T55: 0 | U55: 0 | V55: 0 | W55: 0 | X55: 0 | Y55: 0 | Z55: 0 | AA55: 0 | AB55: 0 | AC55: ='3'!I2 -> 2
A56: ='4'!C2 -> 4.キングストン | B56: 0 | C56: 0 | D56: 0 | E56: 0 | F56: 0 | G56: 0 | H56: 0 | I56: 0 | J56: 0 | K56: 0 | L56: 0 | M56: 0 | N56: 0 | O56: 0 | P56: 0 | Q56: 0 | R56: 0 | S56: 0 | T56: 0 | U56: 0 | V56: 0 | W56: 0 | X56: 0 | Y56: 0 | Z56: 0 | AA56: 0 | AB56: 0 | AC56: ='4'!I2 -> 0
A57: ='5'!$C$2 -> 5.シール類 | B57: 0 | C57: 0 | D57: 0 | E57: 0 | F57: 0 | G57: 0 | H57: 0 | I57: 0 | J57: 0 | K57: 0 | L57: 0 | M57: 0 | N57: 0 | O57: 0 | P57: 0 | Q57: 0 | R57: 0 | S57: 0 | T57: 0 | U57: 0 | V57: 0 | W57: 0 | X57: 0 | Y57: 0 | Z57: 0 | AA57: 0 | AB57: 0 | AC57: ='5'!I2 -> 0
A58: ='6'!C2 -> 6.海水コシ器 | B58: 1 | C58: 1 | D58: 1 | E58: 1 | F58: 3 | G58: 3 | H58: 4 | I58: 4 | J58: 4 | K58: 4 | L58: 2 | M58: 2 | N58: 2 | O58: 1 | P58: 1 | Q58: 1 | R58: 1 | S58: 1 | T58: 1 | U58: 1 | V58: 1 | W58: 1 | X58: 1 | Y58: 2 | Z58: 1 | AA58: 1 | AB58: 1 | AC58: ='6'!I2 -> 0
A59: ='7'!$C$2 -> 7.ペラナット | B59: 0 | C59: 0 | D59: 0 | E59: 0 | F59: 0 | G59: 0 | H59: 0 | I59: 0 | J59: 0 | K59: 0 | L59: 0 | M59: 0 | N59: 0 | O59: 0 | P59: 0 | Q59: 0 | R59: 0 | S59: 0 | T59: 0 | U59: 0 | V59: 0 | W59: 0 | X59: 0 | Y59: 0 | Z59: 0 | AA59: 0 | AB59: 0 | AC59: ='7'!I2 -> 0
A60: ='8'!$C$2 -> 8.ホース類 | B60: 0 | C60: 0 | D60: 0 | E60: 0 | F60: 0 | G60: 0 | H60: 0 | I60: 0 | J60: 0 | K60: 0 | L60: 0 | M60: 0 | N60: 0 | O60: 0 | P60: 0 | Q60: 0 | R60: 0 | S60: 0 | T60: 0 | U60: 0 | V60: 0 | W60: 0 | X60: 0 | Y60: 0 | Z60: 0 | AA60: 0 | AB60: 0 | AC60: ='8'!I2 -> 0
A61: ='9'!C2 -> 9.シールリング | B61: 0 | C61: 0 | D61: 0 | E61: 0 | F61: 0 | G61: 0 | H61: 0 | I61: 0 | J61: 0 | K61: 0 | L61: 0 | M61: 0 | N61: 0 | O61: 0 | P61: 0 | Q61: 0 | R61: 0 | S61: 0 | T61: 0 | U61: 0 | V61: 0 | W61: 0 | X61: 0 | Y61: 0 | Z61: 0 | AA61: 0 | AB61: 0 | AC61: ='9'!I2 -> 0

Sheet 発注点割れ
B41: 46246 | C41: 46251 | D41: 46252 | E41: 46253 | F41: 46254 | G41: 46255 | H41: 46258 | I41: 46259 | J41: 46260 | K41: 46261 | L41: 46262 | M41: 46265 | N41: 46266 | O41: 46267 | P41: 46268 | Q41: 46269 | R41: 46272 | S41: 46273 | T41: 46274 | U41: 46275 | V41: 46276 | W41: 46279 | X41: 46280 | Y41: 46281 | Z41: 46282 | AA41: 46283 | AB41: 46289 | AC41: 46290 | AD41: 46293 | AE41: =TODAY()-AE64 -> 46293
A42: 合計 | B42: =(MAX($B43:$AE43)+MIN($B43:$AE43))/2 -> 116.5 | C42: =(MAX($B43:$AE43)+MIN($B43:$AE43))/2 -> 116.5 | D42: =(MAX($B43:$AE43)+MIN($B43:$AE43))/2 -> 116.5 | E42: =(MAX($B43:$AE43)+MIN($B43:$AE43))/2 -> 116.5 | F42: =(MAX($B43:$AE43)+MIN($B43:$AE43))/2 -> 116.5 | G42: =(MAX($B43:$AE43)+MIN($B43:$AE43))/2 -> 116.5 | H42: =(MAX($B43:$AE43)+MIN($B43:$AE43))/2 -> 116.5 | I42: =(MAX($B43:$AE43)+MIN($B43:$AE43))/2 -> 116.5 | ... AE42: =(MAX($B43:$AE43)+MIN($B43:$AE43))/2 -> 116.5 | AF42: 0.22
A43: 目標 | B43: =SUM(B44:B61) -> 110 | C43: =SUM(C44:C61) -> 106 | D43: =SUM(D44:D61) -> 111 | E43: =SUM(E44:E61) -> 112 | F43: =SUM(F44:F61) -> 117 | G43: =SUM(G44:G61) -> 122 | H43: =SUM(H44:H61) -> 127 | I43: =SUM(I44:I61) -> 119 | ... AE43: =SUM(AE44:AE61) -> 108
A44: ='16'!C2 -> 16.ペラ亜鉛 | B44: 28 | C44: 27 | D44: 28 | E44: 28 | F44: 32 | G44: 32 | H44: 33 | I44: 29 | J44: 29 | K44: 29 | L44: 29 | M44: 30 | N44: 26 | O44: 26 | P44: 26 | Q44: 26 | R44: 27 | S44: 25 | T44: 26 | U44: 26 | V44: 26 | W44: 26 | X44: 21 | Y44: 21 | Z44: 26 | AA44: 24 | AB44: 24 | AC44: 20 | AD44: 20 | AE44: ='16'!G2 -> 21
A45: ='3'!C2 -> 3.スタン | B45: 12 | C45: 11 | D45: 12 | E45: 12 | F45: 14 | G45: 13 | H45: 13 | I45: 15 | J45: 15 | K45: 14 | L45: 15 | M45: 16 | N45: 17 | O45: 17 | P45: 17 | Q45: 14 | R45: 13 | S45: 13 | T45: 12 | U45: 12 | V45: 12 | W45: 13 | X45: 13 | Y45: 13 | Z45: 15 | AA45: 12 | AB45: 12 | AC45: 13 | AD45: 13 | AE45: ='3'!G2 -> 15
A46: ='17'!C2 -> 17.亜鉛板 | B46: 7 | C46: 8 | D46: 8 | E46: 8 | F46: 6 | G46: 5 | H46: 6 | I46: 6 | J46: 7 | K46: 7 | L46: 7 | M46: 7 | N46: 7 | O46: 7 | P46: 7 | Q46: 7 | R46: 9 | S46: 9 | T46: 8 | U46: 8 | V46: 8 | W46: 8 | X46: 8 | Y46: 8 | Z46: 6 | AA46: 8 | AB46: 8 | AC46: 8 | AD46: 8 | AE46: ='17'!G2 -> 6
A47: ='4'!C2 -> 4.キングストン | B47: 9 | C47: 9 | D47: 9 | E47: 9 | F47: 9 | G47: 9 | H47: 9 | I47: 9 | J47: 9 | K47: 9 | L47: 9 | M47: 10 | N47: 10 | O47: 10 | P47: 10 | Q47: 10 | R47: 10 | S47: 10 | T47: 10 | U47: 9 | V47: 9 | W47: 9 | X47: 9 | Y47: 10 | Z47: 11 | AA47: 11 | AB47: 11 | AC47: 12 | AD47: 10 | AE47: ='4'!G2 -> 10
A48: ='12'!C2 -> 12.バルブ類 | B48: 2 | C48: 2 | D48: 2 | E48: 2 | F48: 2 | G48: 2 | H48: 2 | I48: 2 | J48: 2 | K48: 2 | L48: 2 | M48: 2 | N48: 2 | O48: 2 | P48: 2 | Q48: 2 | R48: 2 | S48: 2 | T48: 2 | U48: 2 | V48: 2 | W48: 2 | X48: 2 | Y48: 2 | Z48: 2 | AA48: 2 | AB48: 2 | AC48: 2 | AD48: 2 | AE48: ='12'!G2 -> 2
A49: ='6'!C2 -> 6.海水コシ器 | B49: 12 | C49: 12 | D49: 12 | E49: 12 | F49: 12 | G49: 13 | H49: 14 | I49: 14 | J49: 14 | K49: 13 | L49: 13 | M49: 14 | N49: 12 | O49: 12 | P49: 12 | Q49: 10 | R49: 12 | S49: 13 | T49: 14 | U49: 13 | V49: 13 | W49: 13 | X49: 14 | Y49: 14 | Z49: 15 | AA49: 15 | AB49: 16 | AC49: 15 | AD49: 14 | AE49: ='6'!G2 -> 13
A50: ='11'!C2 -> 11.シール類 | B50: 7 | C50: 6 | D50: 6 | E50: 6 | F50: 6 | G50: 9 | H50: 9 | I50: 9 | J50: 9 | K50: 9 | L50: 10 | M50: 10 | N50: 10 | O50: 10 | P50: 10 | Q50: 10 | R50: 10 | S50: 8 | T50: 8 | U50: 8 | V50: 8 | W50: 8 | X50: 8 | Y50: 8 | Z50: 8 | AA50: 8 | AB50: 8 | AC50: 8 | AD50: 8 | AE50: ='11'!G2 -> 7
A51: ='8'!C2 -> 8.ホース類 | B51: 5 | C51: 5 | D51: 7 | E51: 7 | F51: 7 | G51: 7 | H51: 7 | I51: 7 | J51: 7 | K51: 7 | L51: 7 | M51: 7 | N51: 6 | O51: 7 | P51: 7 | Q51: 6 | R51: 6 | S51: 6 | T51: 5 | U51: 5 | V51: 5 | W51: 5 | X51: 4 | Y51: 4 | Z51: 4 | AA51: 4 | AB51: 4 | AC51: 5 | AD51: 6 | AE51: ='8'!G2 -> 5
A52: ='10'!C2 -> 10.ミキシング | B52: 4 | C52: 4 | D52: 4 | E52: 4 | F52: 4 | G52: 5 | H52: 5 | I52: 6 | J52: 6 | K52: 6 | L52: 5 | M52: 5 | N52: 5 | O52: 5 | P52: 5 | Q52: 4 | R52: 4 | S52: 4 | T52: 4 | U52: 5 | V52: 5 | W52: 5 | X52: 5 | Y52: 6 | Z52: 6 | AA52: 6 | AB52: 6 | AC52: 6 | AD52: 6 | AE52: ='10'!G2 -> 6
A53: ='9'!C2 -> 9.シールリング | B53: 4 | C53: 4 | D53: 4 | E53: 5 | F53: 5 | G53: 5 | H53: 6 | I53: 4 | J53: 3 | K53: 3 | L53: 3 | M53: 3 | N53: 4 | O53: 5 | P53: 6 | Q53: 6 | R53: 6 | S53: 3 | T53: 4 | U53: 4 | V53: 4 | W53: 4 | X53: 4 | Y53: 3 | Z53: 5 | AA53: 5 | AB53: 5 | AC53: 5 | AD53: 5 | AE53: ='9'!G2 -> 5
A54: ='7'!C2 -> 7.ペラナット | B54: 4 | C54: 4 | D54: 4 | E54: 4 | F54: 4 | G54: 4 | H54: 4 | I54: 4 | J54: 4 | K54: 4 | L54: 3 | M54: 3 | N54: 3 | O54: 3 | P54: 3 | Q54: 3 | R54: 3 | S54: 3 | T54: 3 | U54: 3 | V54: 3 | W54: 3 | X54: 3 | Y54: 3 | Z54: 3 | AA54: 3 | AB54: 3 | AC54: 3 | AD54: 3 | AE54: ='7'!G2 -> 3
A55: ='2'!C2 -> 2.ﾕﾆﾊﾞｰｻﾙ | B55: 3 | C55: 3 | D55: 3 | E55: 3 | F55: 3 | G55: 4 | H55: 4 | I55: 1 | J55: 1 | K55: 0 | L55: 0 | M55: 0 | N55: 0 | O55: 0 | P55: 0 | Q55: 0 | R55: 0 | S55: 0 | T55: 0 | U55: 0 | V55: 1 | W55: 1 | X55: 1 | Y55: 1 | Z55: 1 | AA55: 1 | AB55: 1 | AC55: 1 | AD55: 1 | AE55: ='2'!G2 -> 1
A56: ='13'!C2 -> 13.亜鉛棒 | B56: 4 | C56: 4 | D56: 4 | E56: 4 | F56: 5 | G56: 5 | H56: 6 | I56: 6 | J56: 6 | K56: 6 | L56: 7 | M56: 7 | N56: 7 | O56: 7 | P56: 7 | Q56: 7 | R56: 7 | S56: 7 | T56: 7 | U56: 7 | V56: 7 | W56: 7 | X56: 7 | Y56: 6 | Z56: 6 | AA56: 6 | AB56: 6 | AC56: 6 | AD56: 7 | AE56: ='13'!G2 -> 8
A57: ='5'!C2 -> 5.シール類 | B57: 3 | C57: 1 | D57: 2 | E57: 2 | F57: 2 | G57: 3 | H57: 3 | I57: 1 | J57: 2 | K57: 2 | L57: 2 | M57: 2 | N57: 2 | O57: 2 | P57: 2 | Q57: 2 | R57: 3 | S57: 2 | T57: 3 | U57: 4 | V57: 4 | W57: 4 | X57: 4 | Y57: 3 | Z57: 3 | AA57: 3 | AB57: 3 | AC57: 2 | AD57: 2 | AE57: ='5'!G2 -> 2
A58: ='18'!C2 -> 18.ドラム | B58: 0 | C58: 0 | D58: 0 | E58: 0 | F58: 0 | G58: 0 | H58: 0 | I58: 0 | J58: 0 | K58: 0 | L58: 0 | M58: 0 | N58: 0 | O58: 0 | P58: 0 | Q58: 0 | R58: 0 | S58: 0 | T58: 0 | U58: 0 | V58: 0 | W58: 0 | X58: 0 | Y58: 0 | Z58: 0 | AA58: 0 | AB58: 0 | AC58: 0 | AD58: 0 | AE58: ='18'!G2 -> 0
A59: ='14'!C2 -> 14.メタル | B59: 4 | C59: 4 | D59: 4 | E59: 4 | F59: 4 | G59: 4 | H59: 4 | I59: 4 | J59: 4 | K59: 4 | L59: 4 | M59: 4 | N59: 4 | O59: 4 | P59: 4 | Q59: 4 | R59: 4 | S59: 4 | T59: 4 | U59: 4 | V59: 4 | W59: 4 | X59: 4 | Y59: 4 | Z59: 4 | AA59: 4 | AB59: 4 | AC59: 3 | AD59: 3 | AE59: ='14'!G2 -> 3
A60: ='15'!C2 -> 15.ポンプ | B60: 1 | C60: 1 | D60: 1 | E60: 1 | F60: 1 | G60: 1 | H60: 1 | I60: 1 | J60: 1 | K60: 1 | L60: 1 | M60: 1 | N60: 1 | O60: 1 | P60: 1 | Q60: 1 | R60: 1 | S60: 1 | T60: 1 | U60: 1 | V60: 1 | W60: 1 | X60: 1 | Y60: 1 | Z60: 1 | AA60: 1 | AB60: 1 | AC60: 1 | AD60: 1 | AE60: ='15'!G2 -> 1
A61: ='1'!C2 -> 1.その他 | B61: 1 | C61: 1 | D61: 1 | E61: 1 | F61: 1 | G61: 1 | H61: 1 | I61: 1 | J61: 1 | K61: 1 | L61: 1 | M61: 1 | N61: 1 | O61: 1 | P61: 1 | Q61: 0 | R61: 0 | S61: 0 | T61: 0 | U61: 0 | V61: 0 | W61: 0 | X61: 0 | Y61: 0 | Z61: 0 | AA61: 0 | AB61: 0 | AC61: 0 | AD61: 0 | AE61: ='1'!G2 -> 0
AE64: 0

Sheet バーコード貼付
A1: 商品コード | B1: 商品名 | C1: 在庫数 | D1: 発注点
A3: 0500FG | B3: 500FGﾚｲｺｰ燃料ﾌｨﾙﾀｰｾｯﾄ品 | C3: 0 | D3: 10
A4: 0900FH | B4: 0900FHﾚｲｺｰ燃料ﾌｨﾙﾀｰｾｯﾄ品 | C4: 20 | D4: 8
A5: 1000FH | B5: 1000FHﾚｲｺｰ燃料ﾌｨﾙﾀｰｾｯﾄ品 | C5: 0 | D5: 12
A6: 1FB33005 | B6: BCS180*120給水Wｽﾀﾝ後部用筒のみ | C6: 5 | D6: 2
A7: 1FB33006 | B7: BCS180*120前金具給水 | C7: 6 | D7: 1
A8: 1FB33007 | B8: BCS180*115前金具給水 | C8: 1 | D8: 0
A9: 1FB33008 | B9: BCS180*115後金具給水 | C9: 1 | D9: 0
A10: 1FC53002 | B10: BCS170*20TWｽﾀﾝ用丸座金 | C10: 4 | D10: 1
A11: 1FC54002 | B11: BCS77*42ﾊﾟｯｷﾝｸﾞﾗﾝﾄﾞ | C11: 77 | D11: 1
A12: 1FC54003 | B12: BCS96*48ﾊﾟｯｷﾝｸﾞﾗﾝﾄﾞ | C12: 7 | D12: 1
A13: 1FC54004 | B13: BCS110*55ﾊﾟｯｷﾝｸﾞﾗﾝﾄﾞ | C13: 18 | D13: 1
A14: 1FC54005 | B14: BCS120*65ﾊﾟｯｷﾝｸﾞﾗﾝﾄﾞ | C14: 11 | D14: 1
... A53: 80SPH76 | B53: 80SPH(ﾎｰｽ径76)ﾌﾗﾝｼﾞ型ﾎｰｽ海水こし器 | C53: 16 | D53: 36
A54: 8808454 | B54: 8808454亜鉛棒(ﾌﾟﾗｸﾞ付)21φｘ50ｘ77 | C54: 0 | D54: 0
A55: A070R | B55: A-70ｱﾙﾐｶﾞｲﾄﾞﾛｰﾗｰ用ﾛｰﾗｰ | C55: 71 | D55: 0
A56: A090 | B56: A-90ｱﾙﾐｶﾞｲﾄﾞﾛｰﾗｰ | C56: 6 | D56: 0
A57: A090R | B57: A-90ｱﾙﾐｶﾞｲﾄﾞﾛｰﾗｰ用ﾛｰﾗｰ | C57: 18 | D57: 0
A58: A140R | B58: A-140ｱﾙﾐｶﾞｲﾄﾞﾛｰﾗｰ用ﾛｰﾗｰ | C58: 34 | D58: 0
A59: A2K09 | B59: BS3/8ｴｱｰ2方ｺｯｸ | C59: 3 | D59: 1
A60: A31509 | B60: A31509日発用ｸﾗﾝﾌﾟ | C60: 57 | D60: 30
A61: A31538 | B61: A31538日発用ｼﾑ | C61: 62 | D61: 30
A62: A3M015N | B62: (N付)80Rｹｰﾌﾞﾙﾜｲﾔｰ1.5mS-75 | C62: 28 | D62: 2
A63: A3M020N | B63: (N付)80Rｹｰﾌﾞﾙﾜｲﾔｰ2mS-75 | C63: 12 | D63: 3
A64: A3M025N | B64: (N付)80Rｹｰﾌﾞﾙﾜｲﾔｰ2.5mS-75 | C64: 27 | D64: 4
A65: A3M030N | B65: (N付)80Rｹｰﾌﾞﾙﾜｲﾔｰ3mS-75 | C65: 7 | D65: 3
A66: A3M035N | B66: (N付)80Rｹｰﾌﾞﾙﾜｲﾔｰ3.5mS-75 | C66: 26 | D66: 3
... A7422: ZO8A | B7422: Z8-A亜鉛棒17φｘ60ｘ72ｘ84 | C7422: 0 | D7422: 500

Sheet 1
F1: =TODAY()-90 -> 46203
A2: 番号 | B2: コード | C2: 1.その他 | D2: 在庫数 | E2: 発注点 | F2: 発注点割れ | G2: =SUM(G3:G7) -> 0 | H2: 在庫欠品 | I2: =SUM(I3:I7) -> 0 | P2: =P1+1 -> 1
A3: 1 | B3: NAF04065 | C3: =VLOOKUP(B3,バーコード貼付!$A$1:$D$4652,2,FALSE) -> BC5K-65ﾈｼﾞ込合ﾌﾗﾝｼﾞ | D3: =VLOOKUP(B3,バーコード貼付!$A$1:$D$4652,3,FALSE) -> 51 | E3: 7 | G3: =IF(D3-E3>=0,0,1) -> 0 | I3: =IF(AND(D3<=0,D3-E3<0),1,0) -> 0 | O3: =E3-D3 -> -44
A4: 2 | B4: NAF04032 | C4: =VLOOKUP(B4,バーコード貼付!$A$1:$D$4652,2,FALSE) -> BC5K-32ﾈｼﾞ込合ﾌﾗﾝｼﾞ | D4: =VLOOKUP(B4,バーコード貼付!$A$1:$D$4652,3,FALSE) -> 60 | E4: 7 | G4: =IF(D4-E4>=0,0,1) -> 0 | I4: =IF(AND(D4<=0,D4-E4<0),1,0) -> 0 | O4: =E4-D4 -> -53
A5: 3 | B5: FRM04025 | C5: =VLOOKUP(B5,バーコード貼付!$A$1:$D$4652,2,FALSE) -> BC5K-25閉止ﾌﾗﾝｼﾞ直径95 | D5: =VLOOKUP(B5,バーコード貼付!$A$1:$D$4652,3,FALSE) -> 33 | E5: 3 | G5: =IF(D5-E5>=0,0,1) -> 0 | I5: =IF(AND(D5<=0,D5-E5<0),1,0) -> 0
A6: 4 | B6: NAF04020 | C6: =VLOOKUP(B6,バーコード貼付!$A$1:$D$4652,2,FALSE) -> BC5K-20ﾈｼﾞ込合ﾌﾗﾝｼﾞ | D6: =VLOOKUP(B6,バーコード貼付!$A$1:$D$4652,3,FALSE) -> 60 | E6: =VLOOKUP(B6,バーコード貼付!$A$1:$D$4652,4,FALSE) -> 10 | G6: =IF(D6-E6>=0,0,1) -> 0 | I6: =IF(AND(D6<=0,D6-E6<0),1,0) -> 0
A7: 5 | B7: NAF04025 | C7: =VLOOKUP(B7,バーコード貼付!$A$1:$D$4652,2,FALSE) -> BC5K-25ﾈｼﾞ込合ﾌﾗﾝｼﾞ | D7: =VLOOKUP(B7,バーコード貼付!$A$1:$D$4652,3,FALSE) -> 84 | E7: =VLOOKUP(B7,バーコード貼付!$A$1:$D$4652,4,FALSE) -> 10 | G7: =IF(D7-E7>=0,0,1) -> 0 | I7: =IF(AND(D7<=0,D7-E7<0),1,0) -> 0
A8: =A7+1 -> 6

Sheet 2
F1: =TODAY()-90 -> 46203
A2: 番号 | B2: コード | C2: 2.ﾕﾆﾊﾞｰｻﾙ | D2: 在庫数 | E2: 発注点 | F2: 発注点割れ | G2: =SUM(G3:G128) -> 1 | H2: 在庫欠品 | I2: =SUM(I3:I128) -> 0 | P2: =P1+1 -> 1
A3: 1 | B3: CHR03060 | C3: =VLOOKUP(B3,バーコード貼付!$A$1:$D$4652,2,FALSE) -> ﾕﾆ主軸ﾋﾟﾝ用廻り止ﾎﾞﾙﾄ60~75M10*15 | D3: =VLOOKUP(B3,バーコード貼付!$A$1:$D$4652,3,FALSE) -> 1719 | E3: 1723 | F3: 46275 | G3: =IF(D3-E3>=0,0,1) -> 1 | I3: =IF(AND(D3<=0,D3-E3<0),1,0) -> 0 | O3: =E3-D3 -> 4
A4: 2 | B4: CHN06060 | C4: =VLOOKUP(B4,バーコード貼付!$A$1:$D$4652,2,FALSE) -> 真鍮60ﾕﾆﾊﾞｰｻﾙ用主軸ﾋﾟﾝN付銅線付 | D4: =VLOOKUP(B4,バーコード貼付!$A$1:$D$4652,3,FALSE) -> 4 | E4: 1 | G4: =IF(D4-E4>=0,0,1) -> 0 | I4: =IF(AND(D4<=0,D4-E4<0),1,0) -> 0 | O4: =E4-D4 -> -3
A5: 3 | B5: CHP04048 | C5: =VLOOKUP(B5,バーコード貼付!$A$1:$D$4652,2,FALSE) -> BC48~50ﾕﾆﾊﾞｰｻﾙ用ｺﾏ巾73 | D5: =VLOOKUP(B5,バーコード貼付!$A$1:$D$4652,3,FALSE) -> 3 | E5: 3 | G5: =IF(D5-E5>=0,0,1) -> 0 | I5: =IF(AND(D5<=0,D5-E5<0),1,0) -> 0 | O5: =E5-D5 -> 0
A6: 4 | B6: CHR03030 | C6: =VLOOKUP(B6,バーコード貼付!$A$1:$D$4652,2,FALSE) -> ﾕﾆ主軸ﾋﾟﾝ用廻り止ﾎﾞﾙﾄ30~40M6*6 | D6: =VLOOKUP(B6,バーコード貼付!$A$1:$D$4652,3,FALSE) -> 128 | E6: 4 | G6: =IF(D6-E6>=0,0,1) -> 0 | I6: =IF(AND(D6<=0,D6-E6<0),1,0) -> 0 | O6: =E6-D6 -> -124
A7: 5 | B7: CHP04030 | C7: =VLOOKUP(B7,バーコード貼付!$A$1:$D$4652,2,FALSE) -> BC30~32ﾕﾆﾊﾞｰｻﾙ用ｺﾏ巾46 | D7: =VLOOKUP(B7,バーコード貼付!$A$1:$D$4652,3,FALSE) -> 73 | E7: =VLOOKUP(B7,バーコード貼付!$A$1:$D$4652,4,FALSE) -> 5 | G7: =IF(D7-E7>=0,0,1) -> 0 | I7: =IF(AND(D7<=0,D7-E7<0),1,0) -> 0 | O7: =E7-D7 -> -68
A8: 6 | B8: CHR03022 | C8: =VLOOKUP(B8,バーコード貼付!$A$1:$D$4652,2,FALSE) -> ﾕﾆ主軸ﾋﾟﾝ用廻り止ﾎﾞﾙﾄ22~28M5*6 | D8: =VLOOKUP(B8,バーコード貼付!$A$1:$D$4652,3,FALSE) -> 1440 | E8: 3 | G8: =IF(D8-E8>=0,0,1) -> 0 | I8: =IF(AND(D8<=0,D8-E8<0),1,0) -> 0 | O8: =E8-D8 -> -1437
A9: 7 | B9: CHR03042 | C9: =VLOOKUP(B9,バーコード貼付!$A$1:$D$4652,2,FALSE) -> ﾕﾆ主軸ﾋﾟﾝ用廻り止ﾎﾞﾙﾄ42~55M8*10 | D9: =VLOOKUP(B9,バーコード貼付!$A$1:$D$4652,3,FALSE) -> 214 | E9: 2 | G9: =IF(D9-E9>=0,0,1) -> 0 | I9: =IF(AND(D9<=0,D9-E9<0),1,0) -> 0 | O9: =E9-D9 -> -212
A10: 8 | B10: CHN06034 | C10: =VLOOKUP(B10,バーコード貼付!$A$1:$D$4652,2,FALSE) -> 真鍮34~36ﾕﾆﾊﾞｰｻﾙ用主軸ﾋﾟﾝN付銅線付 | D10: =VLOOKUP(B10,バーコード貼付!$A$1:$D$4652,3,FALSE) -> 201 | E10: 18 | G10: =IF(D10-E10>=0,0,1) -> 0 | I10: =IF(AND(D10<=0,D10-E10<0),1,0) -> 0 | O10: =E10-D10 -> -183
A11: 9 | B11: CHK06038 | C11: =VLOOKUP(B11,バーコード貼付!$A$1:$D$4652,2,FALSE) -> 真鍮38~40ﾕﾆﾊﾞｰｻﾙ用ﾉｯｸﾋﾟﾝ | D11: =VLOOKUP(B11,バーコード貼付!$A$1:$D$4652,3,FALSE) -> 221 | E11: =VLOOKUP(B11,バーコード貼付!$A$1:$D$4652,4,FALSE) -> 20 | G11: =IF(D11-E11>=0,0,1) -> 0 | I11: =IF(AND(D11<=0,D11-E11<0),1,0) -> 0 | O11: =E11-D11 -> -201
A12: 10 | B12: CHN06038 | C12: =VLOOKUP(B12,バーコード貼付!$A$1:$D$4652,2,FALSE) -> 真鍮38~40ﾕﾆﾊﾞｰｻﾙ用主軸ﾋﾟﾝN付銅線付 | D12: =VLOOKUP(B12,バーコード貼付!$A$1:$D$4652,3,FALSE) -> 138 | E12: =VLOOKUP(B12,バーコード貼付!$A$1:$D$4652,4,FALSE) -> 50 | G12: =IF(D12-E12>=0,0,1) -> 0 | I12: =IF(AND(D12<=0,D12-E12<0),1,0) -> 0 | O12: =E12-D12 -> -88
A13: 11 | B13: CHN06042 | C13: =VLOOKUP(B13,バーコード貼付!$A$1:$D$4652,2,FALSE) -> 真鍮42~45ﾕﾆﾊﾞｰｻﾙ用主軸ﾋﾟﾝN付銅線付 | D13: =VLOOKUP(B13,バーコード貼付!$A$1:$D$4652,3,FALSE) -> 153 | E13: =VLOOKUP(B13,バーコード貼付!$A$1:$D$4652,4,FALSE) -> 50 | G13: =IF(D13-E13>=0,0,1) -> 0 | I13: =IF(AND(D13<=0,D13-E13<0),1,0) -> 0 | O13: =E13-D13 -> -103
A14: 12 | B14: CHC06022 | C14: =VLOOKUP(B14,バーコード貼付!$A$1:$D$4652,2,FALSE) -> 真鍮22ﾕﾆﾊﾞｰｻﾙ用主軸ｶｼﾒﾋﾟﾝ | D14: =VLOOKUP(B14,バーコード貼付!$A$1:$D$4652,3,FALSE) -> 760 | E14: =VLOOKUP(B14,バーコード貼付!$A$1:$D$4652,4,FALSE) -> 5 | G14: =IF(D14-E14>=0,0,1) -> 0 | I14: =IF(AND(D14<=0,D14-E14<0),1,0) -> 0 | O14: =E14-D14 -> -755
A15: 13 | B15: CHC06025 | C15: =VLOOKUP(B15,バーコード貼付!$A$1:$D$4652,2,FALSE) -> 真鍮25ﾕﾆﾊﾞｰｻﾙ用主軸ｶｼﾒﾋﾟﾝ | D15: =VLOOKUP(B15,バーコード貼付!$A$1:$D$4652,3,FALSE) -> 630 | E15: =VLOOKUP(B15,バーコード貼付!$A$1:$D$4652,4,FALSE) -> 10 | G15: =IF(D15-E15>=0,0,1) -> 0 | I15: =IF(AND(D15<=0,D15-E15<0),1,0) -> 0 | O15: =E15-D15 -> -620
A16: 14 | B16: CHC06028 | C16: =VLOOKUP(B16,バーコード貼付!$A$1:$D$4652,2,FALSE) -> 真鍮28ﾕﾆﾊﾞｰｻﾙ用主軸ｶｼﾒﾋﾟﾝ | D16: =VLOOKUP(B16,バーコード貼付!$A$1:$D$4652,3,FALSE) -> 932 | E16: =VLOOKUP(B16,バーコード貼付!$A$1:$D$4652,4,FALSE) -> 10 | G16: =IF(D16-E16>=0,0,1) -> 0 | I16: =IF(AND(D16<=0,D16-E16<0),1,0) -> 0 | O16: =E16-D16 -> -922
A17: 15 | B17: CHC06030 | C17: =VLOOKUP(B17,バーコード貼付!$A$1:$D$4652,2,FALSE) -> 真鍮30~32ﾕﾆﾊﾞｰｻﾙ用主軸ｶｼﾒﾋﾟﾝ | D17: =VLOOKUP(B17,バーコード貼付!$A$1:$D$4652,3,FALSE) -> 513 | E17: =VLOOKUP(B17,バーコード貼付!$A$1:$D$4652,4,FALSE) -> 10 | G17: =IF(D17-E17>=0,0,1) -> 0 | I17: =IF(AND(D17<=0,D17-E17<0),1,0) -> 0 | O17: =E17-D17 -> -503
A18: 16 | B18: CHC06034 | C18: =VLOOKUP(B18,バーコード貼付!$A$1:$D$4652,2,FALSE) -> 真鍮34~36ﾕﾆﾊﾞｰｻﾙ用主軸ｶｼﾒﾋﾟﾝ | D18: =VLOOKUP(B18,バーコード貼付!$A$1:$D$4652,3,FALSE) -> 233 | E18: =VLOOKUP(B18,バーコード貼付!$A$1:$D$4652,4,FALSE) -> 10 | G18: =IF(D18-E18>=0,0,1) -> 0 | I18: =IF(AND(D18<=0,D18-E18<0),1,0) -> 0 | O18: =E18-D18 -> -223
A19: 17 | B19: CHC06038 | C19: =VLOOKUP(B19,バーコード貼付!$A$1:$D$4652,2,FALSE) -> 真鍮38~40ﾕﾆﾊﾞｰｻﾙ用主軸ｶｼﾒﾋﾟﾝ | D19: =VLOOKUP(B19,バーコード貼付!$A$1:$D$4652,3,FALSE) -> 140 | E19: =VLOOKUP(B19,バーコード貼付!$A$1:$D$4652,4,FALSE) -> 10 | G19: =IF(D19-E19>=0,0,1) -> 0 | I19: =IF(AND(D19<=0,D19-E19<0),1,0) -> 0 | O19: =E19-D19 -> -130
A20: 18 | B20: CHC06042 | C20: =VLOOKUP(B20,バーコード貼付!$A$1:$D$4652,2,FALSE) -> 真鍮42~45ﾕﾆﾊﾞｰｻﾙ用主軸ｶｼﾒﾋﾟﾝ | D20: =VLOOKUP(B20,バーコード貼付!$A$1:$D$4652,3,FALSE) -> 320 | E20: =VLOOKUP(B20,バーコード貼付!$A$1:$D$4652,4,FALSE) -> 10 | G20: =IF(D20-E20>=0,0,1) -> 0 | I20: =IF(AND(D20<=0,D20-E20<0),1,0) -> 0 | O20: =E20-D20 -> -310
A21: 19 | B21: CHC06048 | C21: =VLOOKUP(B21,バーコード貼付!$A$1:$D$4652,2,FALSE) -> 真鍮48~50ﾕﾆﾊﾞｰｻﾙ用主軸ｶｼﾒﾋﾟﾝ | D21: =VLOOKUP(B21,バーコード貼付!$A$1:$D$4652,3,FALSE) -> 224 | E21: =VLOOKUP(B21,バーコード貼付!$A$1:$D$4652,4,FALSE) -> 10 | G21: =IF(D21-E21>=0,0,1) -> 0 | I21: =IF(AND(D21<=0,D21-E21<0),1,0) -> 0 | O21: =E21-D21 -> -214
A22: 20 | B22: CHC06055 | C22: =VLOOKUP(B22,バーコード貼付!$A$1:$D$4652,2,FALSE) -> 真鍮55ﾕﾆﾊﾞｰｻﾙ用主軸ｶｼﾒﾋﾟﾝ | D22: =VLOOKUP(B22,バーコード貼付!$A$1:$D$4652,3,FALSE) -> 81 | E22: 81 | G22: =IF(D22-E22>=0,0,1) -> 0 | I22: =IF(AND(D22<=0,D22-E22<0),1,0) -> 0 | O22: =E22-D22 -> 0
A23: 21 | B23: CHC06060 | C23: =VLOOKUP(B23,バーコード貼付!$A$1:$D$4652,2,FALSE) -> 真鍮60ﾕﾆﾊﾞｰｻﾙ用主軸ｶｼﾒﾋﾟﾝ | D23: =VLOOKUP(B23,バーコード貼付!$A$1:$D$4652,3,FALSE) -> 191 | E23: =VLOOKUP(B23,バーコード貼付!$A$1:$D$4652,4,FALSE) -> 5 | G23: =IF(D23-E23>=0,0,1) -> 0 | I23: =IF(AND(D23<=0,D23-E23<0),1,0) -> 0 | O23: =E23-D23 -> -186
A24: 22 | B24: CHK06022 | C24: =VLOOKUP(B24,バーコード貼付!$A$1:$D$4652,2,FALSE) -> 真鍮22ﾕﾆﾊﾞｰｻﾙ用ﾉｯｸﾋﾟﾝ | D24: =VLOOKUP(B24,バーコード貼付!$A$1:$D$4652,3,FALSE) -> 384 | E24: =VLOOKUP(B24,バーコード貼付!$A$1:$D$4652,4,FALSE) -> 30 | G24: =IF(D24-E24>=0,0,1) -> 0 | I24: =IF(AND(D24<=0,D24-E24<0),1,0) -> 0 | O24: =E24-D24 -> -354
A25: 23 | B25: CHK06025 | C25: =VLOOKUP(B25,バーコード貼付!$A$1:$D$4652,2,FALSE) -> 真鍮25ﾕﾆﾊﾞｰｻﾙ用ﾉｯｸﾋﾟﾝ | D25: =VLOOKUP(B25,バーコード貼付!$A$1:$D$4652,3,FALSE) -> 151 | E25: =VLOOKUP(B25,バーコード貼付!$A$1:$D$4652,4,FALSE) -> 30 | G25: =IF(D25-E25>=0,0,1) -> 0 | I25: =IF(AND(D25<=0,D25-E25<0),1,0) -> 0 | O25: =E25-D25 -> -121
A26: 24 | B26: CHK06028 | C26: =VLOOKUP(B26,バーコード貼付!$A$1:$D$4652,2,FALSE) -> 真鍮28ﾕﾆﾊﾞｰｻﾙ用ﾉｯｸﾋﾟﾝ | D26: =VLOOKUP(B26,バーコード貼付!$A$1:$D$4652,3,FALSE) -> 81 | E26: =VLOOKUP(B26,バーコード貼付!$A$1:$D$4652,4,FALSE) -> 30 | G26: =IF(D26-E26>=0,0,1) -> 0 | I26: =IF(AND(D26<=0,D26-E26<0),1,0) -> 0 | O26: =E26-D26 -> -51
A27: 25 | B27: CHK06030 | C27: =VLOOKUP(B27,バーコード貼付!$A$1:$D$4652,2,FALSE) -> 真鍮30~32ﾕﾆﾊﾞｰｻﾙ用ﾉｯｸﾋﾟﾝ | D27: =VLOOKUP(B27,バーコード貼付!$A$1:$D$4652,3,FALSE) -> 79 | E27: =VLOOKUP(B27,バーコード貼付!$A$1:$D$4652,4,FALSE) -> 30 | G27: =IF(D27-E27>=0,0,1) -> 0 | I27: =IF(AND(D27<=0,D27-E27<0),1,0) -> 0 | O27: =E27-D27 -> -49
A28: 26 | B28: CHK06034 | C28: =VLOOKUP(B28,バーコード貼付!$A$1:$D$4652,2,FALSE) -> 真鍮34~36ﾕﾆﾊﾞｰｻﾙ用ﾉｯｸﾋﾟﾝ | D28: =VLOOKUP(B28,バーコード貼付!$A$1:$D$4652,3,FALSE) -> 27 | E28: =VLOOKUP(B28,バーコード貼付!$A$1:$D$4652,4,FALSE) -> 15 | G28: =IF(D28-E28>=0,0,1) -> 0 | I28: =IF(AND(D28<=0,D28-E28<0),1,0) -> 0 | O28: =E28-D28 -> -12
A29: 27 | B29: CHK06042 | C29: =VLOOKUP(B29,バーコード貼付!$A$1:$D$4652,2,FALSE) -> 真鍮42~45ﾕﾆﾊﾞｰｻﾙ用ﾉｯｸﾋﾟﾝ | D29: =VLOOKUP(B29,バーコード貼付!$A$1:$D$4652,3,FALSE) -> 64 | E29: =VLOOKUP(B29,バーコード貼付!$A$1:$D$4652,4,FALSE) -> 10 | G29: =IF(D29-E29>=0,0,1) -> 0 | I29: =IF(AND(D29<=0,D29-E29<0),1,0) -> 0 | O29: =E29-D29 -> -54
A30: 28 | B30: CHK06048 | C30: =VLOOKUP(B30,バーコード貼付!$A$1:$D$4652,2,FALSE) -> 真鍮48~50ﾕﾆﾊﾞｰｻﾙ用ﾉｯｸﾋﾟﾝ | D30: =VLOOKUP(B30,バーコード貼付!$A$1:$D$4652,3,FALSE) -> 71 | E30: =VLOOKUP(B30,バーコード貼付!$A$1:$D$4652,4,FALSE) -> 30 | G30: =IF(D30-E30>=0,0,1) -> 0 | I30: =IF(AND(D30<=0,D30-E30<0),1,0) -> 0 | O30: =E30-D30 -> -41
A31: 29 | B31: CHK06055 | C31: =VLOOKUP(B31,バーコード貼付!$A$1:$D$4652,2,FALSE) -> 真鍮55ﾕﾆﾊﾞｰｻﾙ用ﾉｯｸﾋﾟﾝ | D31: =VLOOKUP(B31,バーコード貼付!$A$1:$D$4652,3,FALSE) -> 203 | E31: =VLOOKUP(B31,バーコード貼付!$A$1:$D$4652,4,FALSE) -> 20 | G31: =IF(D31-E31>=0,0,1) -> 0 | I31: =IF(AND(D31<=0,D31-E31<0),1,0) -> 0 | O31: =E31-D31 -> -183
A32: 30 | B32: CHK06060 | C32: =VLOOKUP(B32,バーコード貼付!$A$1:$D$4652,2,FALSE) -> 真鍮60ﾕﾆﾊﾞｰｻﾙ用ﾉｯｸﾋﾟﾝ | D32: =VLOOKUP(B32,バーコード貼付!$A$1:$D$4652,3,FALSE) -> 35 | E32: =VLOOKUP(B32,バーコード貼付!$A$1:$D$4652,4,FALSE) -> 20 | G32: =IF(D32-E32>=0,0,1) -> 0 | I32: =IF(AND(D32<=0,D32-E32<0),1,0) -> 0 | O32: =E32-D32 -> -15
A33: 31 | B33: CHK06065 | C33: =VLOOKUP(B33,バーコード貼付!$A$1:$D$4652,2,FALSE) -> 真鍮65ﾕﾆﾊﾞｰｻﾙ用ﾉｯｸﾋﾟﾝ | D33: =VLOOKUP(B33,バーコード貼付!$A$1:$D$4652,3,FALSE) -> 290 | E33: =VLOOKUP(B33,バーコード貼付!$A$1:$D$4652,4,FALSE) -> 10 | G33: =IF(D33-E33>=0,0,1) -> 0 | I33: =IF(AND(D33<=0,D33-E33<0),1,0) -> 0 | O33: =E33-D33 -> -280
A34: 32 | B34: CHK06070 | C34: =VLOOKUP(B34,バーコード貼付!$A$1:$D$4652,2,FALSE) -> 真鍮70ﾕﾆﾊﾞｰｻﾙ用ﾉｯｸﾋﾟﾝ | D34: =VLOOKUP(B34,バーコード貼付!$A$1:$D$4652,3,FALSE) -> 31 | E34: =VLOOKUP(B34,バーコード貼付!$A$1:$D$4652,4,FALSE) -> 10 | G34: =IF(D34-E34>=0,0,1) -> 0 | I34: =IF(AND(D34<=0,D34-E34<0),1,0) -> 0 | O34: =E34-D34 -> -21
... A37: 35 | B37: CHK06085 | C37: =VLOOKUP(B37,バーコード貼付!$A$1:$D$4652,2,FALSE) -> 真鍮85~90ﾕﾆﾊﾞｰｻﾙ用ﾉｯｸﾋﾟﾝ | D37: =VLOOKUP(B37,バーコード貼付!$A$1:$D$4652,3,FALSE) -> 227 | E37: =VLOOKUP(B37,バーコード貼付!$A$1:$D$4652,4,FALSE) -> 10 | G37: =IF(D37-E37>=0,0,1) -> 0 | I37: =IF(AND(D37<=0,D37-E37<0),1,0) -> 0 | O37: =E37-D37 -> -217
A38: 36 | B38: CHK06090 | C38: =VLOOKUP(B38,バーコード貼付!$A$1:$D$4652,2,FALSE) -> 真鍮90ﾕﾆﾊﾞｰｻﾙ用ﾉｯｸﾋﾟﾝ | D38: =VLOOKUP(B38,バーコード貼付!$A$1:$D$4652,3,FALSE) -> 113 | E38: 113 | G38: =IF(D38-E38>=0,0,1) -> 0 | I38: =IF(AND(D38<=0,D38-E38<0),1,0) -> 0 | O38: =E38-D38 -> 0
A39: 37 | B39: CHK06105 | C39: =VLOOKUP(B39,バーコード貼付!$A$1:$D$4652,2,FALSE) -> 真鍮105ﾕﾆﾊﾞｰｻﾙ用ﾉｯｸﾋﾟﾝ | D39: =VLOOKUP(B39,バーコード貼付!$A$1:$D$4652,3,FALSE) -> 70 | E39: =VLOOKUP(B39,バーコード貼付!$A$1:$D$4652,4,FALSE) -> 5 | G39: =IF(D39-E39>=0,0,1) -> 0 | I39: =IF(AND(D39<=0,D39-E39<0),1,0) -> 0 | O39: =E39-D39 -> -65
A40: 38 | B40: CHN06022 | C40: =VLOOKUP(B40,バーコード貼付!$A$1:$D$4652,2,FALSE) -> 真鍮22ﾕﾆﾊﾞｰｻﾙ用主軸ﾋﾟﾝN付銅線付 | D40: =VLOOKUP(B40,バーコード貼付!$A$1:$D$4652,3,FALSE) -> 707 | E40: =VLOOKUP(B40,バーコード貼付!$A$1:$D$4652,4,FALSE) -> 10 | G40: =IF(D40-E40>=0,0,1) -> 0 | I40: =IF(AND(D40<=0,D40-E40<0),1,0) -> 0 | O40: =E40-D40 -> -697
A41: 39 | B41: CHN06025 | C41: =VLOOKUP(B41,バーコード貼付!$A$1:$D$4652,2,FALSE) -> 真鍮25ﾕﾆﾊﾞｰｻﾙ用主軸ﾋﾟﾝN付銅線付 | D41: =VLOOKUP(B41,バーコード貼付!$A$1:$D$4652,3,FALSE) -> 320 | E41: =VLOOKUP(B41,バーコード貼付!$A$1:$D$4652,4,FALSE) -> 50 | G41: =IF(D41-E41>=0,0,1) -> 0 | I41: =IF(AND(D41<=0,D41-E41<0),1,0) -> 0 | O41: =E41-D41 -> -270
A42: 40 | B42: CHN06028 | C42: =VLOOKUP(B42,バーコード貼付!$A$1:$D$4652,2,FALSE) -> 真鍮28ﾕﾆﾊﾞｰｻﾙ用主軸ﾋﾟﾝN付銅線付 | D42: =VLOOKUP(B42,バーコード貼付!$A$1:$D$4652,3,FALSE) -> 438 | E42: =VLOOKUP(B42,バーコード貼付!$A$1:$D$4652,4,FALSE) -> 20 | G42: =IF(D42-E42>=0,0,1) -> 0 | I42: =IF(AND(D42<=0,D42-E42<0),1,0) -> 0 | O42: =E42-D42 -> -418
...

Sheet 3
F1: =TODAY()-90 -> 46203
A2: 番号 | B2: コード | C2: 3.スタン | D2: 在庫数 | E2: 発注点 | F2: 発注点割れ | G2: =SUM(G3:G338) -> 15 | H2: 在庫欠品 | I2: =SUM(I3:I338) -> 2 | P2: =P1+1 -> 1
A3: 1 | B3: UC055 | C3: =VLOOKUP(B3,バーコード貼付!$A$1:$D$4652,2,FALSE) -> 軸55TWｼｰﾙｽﾀﾝ用ｶｰﾎﾞﾝﾌﾞﾗｼ(ｾｯﾄ品) | D3: =VLOOKUP(B3,バーコード貼付!$A$1:$D$4652,3,FALSE) -> 0 | E3: 25 | F3: 46251 | G3: =IF(D3-E3>=0,0,1) -> 1 | H3: 46293 | I3: =IF(AND(D3<=0,D3-E3<0),1,0) -> 1 | O3: =E3-D3 -> 25
A4: 2 | B4: TSP60Y | C4: =VLOOKUP(B4,バーコード貼付!$A$1:$D$4652,2,FALSE) -> TSP60Yｼｰﾙｽﾀﾝ(ﾔﾏﾊ仕様) | D4: =VLOOKUP(B4,バーコード貼付!$A$1:$D$4652,3,FALSE) -> 5 | E4: 6 | F4: 46213 | G4: =IF(D4-E4>=0,0,1) -> 1 | I4: =IF(AND(D4<=0,D4-E4<0),1,0) -> 0 | O4: =E4-D4 -> 1
A5: 3 | B5: CT04060 | C5: =VLOOKUP(B5,バーコード貼付!$A$1:$D$4652,2,FALSE) -> BC60(S96)S型単式ｽﾀﾝL1*250 | D5: =VLOOKUP(B5,バーコード貼付!$A$1:$D$4652,3,FALSE) -> 1 | E5: 2 | F5: 46217 | G5: =IF(D5-E5>=0,0,1) -> 1 | I5: =IF(AND(D5<=0,D5-E5<0),1,0) -> 0 | O5: =E5-D5 -> 1
A6: 4 | B6: TO04075 | C6: =VLOOKUP(B6,バーコード貼付!$A$1:$D$4652,2,FALSE) -> BCS120*75TSS型前部ｽﾀﾝﾎﾞｯｸｽ | D6: =VLOOKUP(B6,バーコード貼付!$A$1:$D$4652,3,FALSE) -> 4 | E6: =VLOOKUP(B6,バーコード貼付!$A$1:$D$4652,4,FALSE) -> 5 | F6: 46237 | G6: =IF(D6-E6>=0,0,1) -> 1 | I6: =IF(AND(D6<=0,D6-E6<0),1,0) -> 0 | O6: =E6-D6 -> 1
A7: 5 | B7: TO04085 | C7: =VLOOKUP(B7,バーコード貼付!$A$1:$D$4652,2,FALSE) -> BCS140*85TSS型前部ｽﾀﾝﾎﾞｯｸｽ | D7: =VLOOKUP(B7,バーコード貼付!$A$1:$D$4652,3,FALSE) -> 3 | E7: =VLOOKUP(B7,バーコード貼付!$A$1:$D$4652,4,FALSE) -> 4 | F7: 46239 | G7: =IF(D7-E7>=0,0,1) -> 1 | I7: =IF(AND(D7<=0,D7-E7<0),1,0) -> 0 | O7: =E7-D7 -> 1
A8: 6 | B8: UC070 | C8: =VLOOKUP(B8,バーコード貼付!$A$1:$D$4652,2,FALSE) -> 軸70TWｼｰﾙｽﾀﾝ用ｶｰﾎﾞﾝﾌﾞﾗｼ(ｾｯﾄ品) | D8: =VLOOKUP(B8,バーコード貼付!$A$1:$D$4652,3,FALSE) -> 16 | E8: 41 | F8: 46240 | G8: =IF(D8-E8>=0,0,1) -> 1 | I8: =IF(AND(D8<=0,D8-E8<0),1,0) -> 0 | O8: =E8-D8 -> 25
A9: 7 | B9: CU04034 | C9: =VLOOKUP(B9,バーコード貼付!$A$1:$D$4652,2,FALSE) -> BC34単式ｽﾀﾝ検査品用L1*172 | D9: =VLOOKUP(B9,バーコード貼付!$A$1:$D$4652,3,FALSE) -> 1 | E9: 2 | F9: 46265 | G9: =IF(D9-E9>=0,0,1) -> 1 | I9: =IF(AND(D9<=0,D9-E9<0),1,0) -> 0 | O9: =E9-D9 -> 1
A10: 8 | B10: TSA070701 | C10: =VLOOKUP(B10,バーコード貼付!$A$1:$D$4652,2,FALSE) -> TSAS110*70ｼｰﾙｱﾀﾞﾌﾟﾀｰ給水用 | D10: =VLOOKUP(B10,バーコード貼付!$A$1:$D$4652,3,FALSE) -> 4 | E10: 5 | F10: 46258 | G10: =IF(D10-E10>=0,0,1) -> 1 | I10: =IF(AND(D10<=0,D10-E10<0),1,0) -> 0 | O10: =E10-D10 -> 1
A11: 9 | B11: TSP55H | C11: =VLOOKUP(B11,バーコード貼付!$A$1:$D$4652,2,FALSE) -> S91*軸55TSP型ｼｰﾙｽﾀﾝ用前部金具 | D11: =VLOOKUP(B11,バーコード貼付!$A$1:$D$4652,3,FALSE) -> 3 | E11: 4 | F11: 46276 | G11: =IF(D11-E11>=0,0,1) -> 1 | I11: =IF(AND(D11<=0,D11-E11<0),1,0) -> 0 | O11: =E11-D11 -> 1
A12: 10 | B12: UC050 | C12: =VLOOKUP(B12,バーコード貼付!$A$1:$D$4652,2,FALSE) -> 軸50TWｼｰﾙｽﾀﾝ用ｶｰﾎﾞﾝﾌﾞﾗｼ(ｾｯﾄ品) | D12: =VLOOKUP(B12,バーコード貼付!$A$1:$D$4652,3,FALSE) -> 26 | E12: =VLOOKUP(B12,バーコード貼付!$A$1:$D$4652,4,FALSE) -> 30 | F12: 46281 | G12: =IF(D12-E12>=0,0,1) -> 1 | I12: =IF(AND(D12<=0,D12-E12<0),1,0) -> 0 | O12: =E12-D12 -> 4
A13: 11 | B13: TSP65Y | C13: =VLOOKUP(B13,バーコード貼付!$A$1:$D$4652,2,FALSE) -> TSP65Yｼｰﾙｽﾀﾝ(ﾔﾏﾊ仕様) | D13: =VLOOKUP(B13,バーコード貼付!$A$1:$D$4652,3,FALSE) -> 5 | E13: 6 | F13: 46281 | G13: =IF(D13-E13>=0,0,1) -> 1 | I13: =IF(AND(D13<=0,D13-E13<0),1,0) -> 0 | O13: =E13-D13 -> 1
A14: 12 | B14: EG0430381 | C14: =VLOOKUP(B14,バーコード貼付!$A$1:$D$4652,2,FALSE) -> BCWF70*38給水用ﾊﾟｯｷﾝｸﾞﾗﾝﾄﾞ | D14: =VLOOKUP(B14,バーコード貼付!$A$1:$D$4652,3,FALSE) -> 49 | E14: 50 | F14: 46281 | G14: =IF(D14-E14>=0,0,1) -> 1 | I14: =IF(AND(D14<=0,D14-E14<0),1,0) -> 0 | O14: =E14-D14 -> 1
A15: 13 | B15: TSA070801 | C15: =VLOOKUP(B15,バーコード貼付!$A$1:$D$4652,2,FALSE) -> TSAS127*80ｼｰﾙｱﾀﾞﾌﾟﾀｰ給水用 | D15: =VLOOKUP(B15,バーコード貼付!$A$1:$D$4652,3,FALSE) -> 1 | E15: 3 | F15: 46289 | G15: =IF(D15-E15>=0,0,1) -> 1 | I15: =IF(AND(D15<=0,D15-E15<0),1,0) -> 0 | O15: =E15-D15 -> 2
A16: 14 | B16: TO04100 | C16: =VLOOKUP(B16,バーコード貼付!$A$1:$D$4652,2,FALSE) -> BCS160*100TSS型前部ｽﾀﾝﾎﾞｯｸｽ | D16: =VLOOKUP(B16,バーコード貼付!$A$1:$D$4652,3,FALSE) -> 0 | E16: 2 | F16: 46293 | G16: =IF(D16-E16>=0,0,1) -> 1 | H16: 46293 | I16: =IF(AND(D16<=0,D16-E16<0),1,0) -> 1 | O16: =E16-D16 -> 2
A17: 15 | B17: CU04060 | C17: =VLOOKUP(B17,バーコード貼付!$A$1:$D$4652,2,FALSE) -> BC60単式ｽﾀﾝ検査品用L1*285 | D17: =VLOOKUP(B17,バーコード貼付!$A$1:$D$4652,3,FALSE) -> 2 | E17: =VLOOKUP(B17,バーコード貼付!$A$1:$D$4652,4,FALSE) -> 3 | F17: 46293 | G17: =IF(D17-E17>=0,0,1) -> 1 | I17: =IF(AND(D17<=0,D17-E17<0),1,0) -> 0 | O17: =E17-D17 -> 1
A18: 16 | B18: TSA070751 | C18: =VLOOKUP(B18,バーコード貼付!$A$1:$D$4652,2,FALSE) -> TSAS120*75ｼｰﾙｱﾀﾞﾌﾟﾀｰ給水用 | D18: =VLOOKUP(B18,バーコード貼付!$A$1:$D$4652,3,FALSE) -> 4 | E18: 2 | G18: =IF(D18-E18>=0,0,1) -> 0 | I18: =IF(AND(D18<=0,D18-E18<0),1,0) -> 0 | O18: =E18-D18 -> -2
A19: 17 | B19: TSP70H | C19: =VLOOKUP(B19,バーコード貼付!$A$1:$D$4652,2,FALSE) -> S111*軸70TSP型ｼｰﾙｽﾀﾝ用前部金具 | D19: =VLOOKUP(B19,バーコード貼付!$A$1:$D$4652,3,FALSE) -> 6 | E19: 5 | G19: =IF(D19-E19>=0,0,1) -> 0 | I19: =IF(AND(D19<=0,D19-E19<0),1,0) -> 0 | O19: =E19-D19 -> -1
A20: 18 | B20: TSP80H | C20: =VLOOKUP(B20,バーコード貼付!$A$1:$D$4652,2,FALSE) -> S129*軸80TSP型ｼｰﾙｽﾀﾝ用前部金具 | D20: =VLOOKUP(B20,バーコード貼付!$A$1:$D$4652,3,FALSE) -> 4 | E20: 4 | G20: =IF(D20-E20>=0,0,1) -> 0 | I20: =IF(AND(D20<=0,D20-E20<0),1,0) -> 0 | O20: =E20-D20 -> 0
A21: 19 | B21: TO04070 | C21: =VLOOKUP(B21,バーコード貼付!$A$1:$D$4652,2,FALSE) -> BCS110*70TSS型前部ｽﾀﾝﾎﾞｯｸｽ | D21: =VLOOKUP(B21,バーコード貼付!$A$1:$D$4652,3,FALSE) -> 6 | E21: 4 | G21: =IF(D21-E21>=0,0,1) -> 0 | I21: =IF(AND(D21<=0,D21-E21<0),1,0) -> 0 | O21: =E21-D21 -> -2
A22: 20 | B22: TO04095 | C22: =VLOOKUP(B22,バーコード貼付!$A$1:$D$4652,2,FALSE) -> BCS150*95TSS型前部ｽﾀﾝﾎﾞｯｸｽ | D22: =VLOOKUP(B22,バーコード貼付!$A$1:$D$4652,3,FALSE) -> 10 | E22: 6 | G22: =IF(D22-E22>=0,0,1) -> 0 | I22: =IF(AND(D22<=0,D22-E22<0),1,0) -> 0 | O22: =E22-D22 -> -4
A23: 21 | B23: TSP65H | C23: =VLOOKUP(B23,バーコード貼付!$A$1:$D$4652,2,FALSE) -> S104*軸65TSP型ｼｰﾙｽﾀﾝ用前部金具 | D23: =VLOOKUP(B23,バーコード貼付!$A$1:$D$4652,3,FALSE) -> 10 | E23: 2 | G23: =IF(D23-E23>=0,0,1) -> 0 | I23: =IF(AND(D23<=0,D23-E23<0),1,0) -> 0 | O23: =E23-D23 -> -8
A24: 22 | B24: TSA070551 | C24: =VLOOKUP(B24,バーコード貼付!$A$1:$D$4652,2,FALSE) -> TSAS96*55ｼｰﾙｱﾀﾞﾌﾟﾀｰ給水用 | D24: =VLOOKUP(B24,バーコード貼付!$A$1:$D$4652,3,FALSE) -> 3 | E24: 3 | G24: =IF(D24-E24>=0,0,1) -> 0 | I24: =IF(AND(D24<=0,D24-E24<0),1,0) -> 0 | O24: =E24-D24 -> 0
A25: 23 | B25: TSA070651 | C25: =VLOOKUP(B25,バーコード貼付!$A$1:$D$4652,2,FALSE) -> TSAS110*65ｼｰﾙｱﾀﾞﾌﾟﾀｰ給水用 | D25: =VLOOKUP(B25,バーコード貼付!$A$1:$D$4652,3,FALSE) -> 4 | E25: 4 | G25: =IF(D25-E25>=0,0,1) -> 0 | I25: =IF(AND(D25<=0,D25-E25<0),1,0) -> 0 | O25: =E25-D25 -> 0
A26: 24 | B26: TSA070451 | C26: =VLOOKUP(B26,バーコード貼付!$A$1:$D$4652,2,FALSE) -> TSAS77*45ｼｰﾙｱﾀﾞﾌﾟﾀｰ給水用 | D26: =VLOOKUP(B26,バーコード貼付!$A$1:$D$4652,3,FALSE) -> 4 | E26: =VLOOKUP(B26,バーコード貼付!$A$1:$D$4652,4,FALSE) -> 2 | G26: =IF(D26-E26>=0,0,1) -> 0 | I26: =IF(AND(D26<=0,D26-E26<0),1,0) -> 0 | O26: =E26-D26 -> -2
A27: 25 | B27: TSP60H | C27: =VLOOKUP(B27,バーコード貼付!$A$1:$D$4652,2,FALSE) -> S96*軸60TSP型ｼｰﾙｽﾀﾝ用前部金具 | D27: =VLOOKUP(B27,バーコード貼付!$A$1:$D$4652,3,FALSE) -> 5 | E27: 5 | G27: =IF(D27-E27>=0,0,1) -> 0 | I27: =IF(AND(D27<=0,D27-E27<0),1,0) -> 0 | O27: =E27-D27 -> 0
A28: 26 | B28: TSA070901 | C28: =VLOOKUP(B28,バーコード貼付!$A$1:$D$4652,2,FALSE) -> TSAS150*90ｼｰﾙｱﾀﾞﾌﾟﾀｰ給水用 | D28: =VLOOKUP(B28,バーコード貼付!$A$1:$D$4652,3,FALSE) -> 4 | E28: 3 | G28: =IF(D28-E28>=0,0,1) -> 0 | I28: =IF(AND(D28<=0,D28-E28<0),1,0) -> 0 | O28: =E28-D28 -> -1
A29: 27 | B29: TSP75H | C29: =VLOOKUP(B29,バーコード貼付!$A$1:$D$4652,2,FALSE) -> S117*軸75TSP型ｼｰﾙｽﾀﾝ用前部金具 | D29: =VLOOKUP(B29,バーコード貼付!$A$1:$D$4652,3,FALSE) -> 7 | E29: 6 | G29: =IF(D29-E29>=0,0,1) -> 0 | I29: =IF(AND(D29<=0,D29-E29<0),1,0) -> 0 | O29: =E29-D29 -> -1
A30: 28 | B30: UC060 | C30: =VLOOKUP(B30,バーコード貼付!$A$1:$D$4652,2,FALSE) -> 軸60TWｼｰﾙｽﾀﾝ用ｶｰﾎﾞﾝﾌﾞﾗｼ(ｾｯﾄ品) | D30: =VLOOKUP(B30,バーコード貼付!$A$1:$D$4652,3,FALSE) -> 45 | E30: 38 | G30: =IF(D30-E30>=0,0,1) -> 0 | I30: =IF(AND(D30<=0,D30-E30<0),1,0) -> 0 | O30: =E30-D30 -> -7
A31: 29 | B31: TSP75Y | C31: =VLOOKUP(B31,バーコード貼付!$A$1:$D$4652,2,FALSE) -> TSP75Yｼｰﾙｽﾀﾝ(ﾔﾏﾊ仕様) | D31: =VLOOKUP(B31,バーコード貼付!$A$1:$D$4652,3,FALSE) -> 6 | E31: 2 | G31: =IF(D31-E31>=0,0,1) -> 0 | I31: =IF(AND(D31<=0,D31-E31<0),1,0) -> 0 | O31: =E31-D31 -> -4
A32: 30 | B32: TSA070851 | C32: =VLOOKUP(B32,バーコード貼付!$A$1:$D$4652,2,FALSE) -> TSAS140*85ｼｰﾙｱﾀﾞﾌﾟﾀｰ給水用 | D32: =VLOOKUP(B32,バーコード貼付!$A$1:$D$4652,3,FALSE) -> 3 | E32: 3 | G32: =IF(D32-E32>=0,0,1) -> 0 | I32: =IF(AND(D32<=0,D32-E32<0),1,0) -> 0 | O32: =E32-D32 -> 0
A33: 31 | B33: TSA070401 | C33: =VLOOKUP(B33,バーコード貼付!$A$1:$D$4652,2,FALSE) -> TSAS70*40ｼｰﾙｱﾀﾞﾌﾟﾀｰ給水用 | D33: =VLOOKUP(B33,バーコード貼付!$A$1:$D$4652,3,FALSE) -> 4 | E33: =VLOOKUP(B33,バーコード貼付!$A$1:$D$4652,4,FALSE) -> 2 | G33: =IF(D33-E33>=0,0,1) -> 0 | I33: =IF(AND(D33<=0,D33-E33<0),1,0) -> 0 | O33: =E33-D33 -> -2
A34: 32 | B34: EG0430501 | C34: =VLOOKUP(B34,バーコード貼付!$A$1:$D$4652,2,FALSE) -> BCWF88*50給水用ﾊﾟｯｷﾝｸﾞﾗﾝﾄﾞ | D34: =VLOOKUP(B34,バーコード貼付!$A$1:$D$4652,3,FALSE) -> 8 | E34: 2 | G34: =IF(D34-E34>=0,0,1) -> 0 | I34: =IF(AND(D34<=0,D34-E34<0),1,0) -> 0 | O34: =E34-D34 -> -6
A35: 33 | B35: TSP50Y | C35: =VLOOKUP(B35,バーコード貼付!$A$1:$D$4652,2,FALSE) -> TSP50Yｼｰﾙｽﾀﾝ(ﾔﾏﾊ仕様) | D35: =VLOOKUP(B35,バーコード貼付!$A$1:$D$4652,3,FALSE) -> 5 | E35: =VLOOKUP(B35,バーコード貼付!$A$1:$D$4652,4,FALSE) -> 5 | G35: =IF(D35-E35>=0,0,1) -> 0 | I35: =IF(AND(D35<=0,D35-E35<0),1,0) -> 0 | O35: =E35-D35 -> 0
A36: 34 | B36: TSA070951 | C36: =VLOOKUP(B36,バーコード貼付!$A$1:$D$4652,2,FALSE) -> TSAS150*95ｼｰﾙｱﾀﾞﾌﾟﾀｰ給水用 | D36: =VLOOKUP(B36,バーコード貼付!$A$1:$D$4652,3,FALSE) -> 3 | E36: 3 | G36: =IF(D36-E36>=0,0,1) -> 0 | I36: =IF(AND(D36<=0,D36-E36<0),1,0) -> 0 | O36: =E36-D36 -> 0
A37: 35 | B37: UC065 | C37: =VLOOKUP(B37,バーコード貼付!$A$1:$D$4652,2,FALSE) -> 軸65TWｼｰﾙｽﾀﾝ用ｶｰﾎﾞﾝﾌﾞﾗｼ(ｾｯﾄ品) | D37: =VLOOKUP(B37,バーコード貼付!$A$1:$D$4652,3,FALSE) -> 60 | E37: 24 | G37: =IF(D37-E37>=0,0,1) -> 0 | I37: =IF(AND(D37<=0,D37-E37<0),1,0) -> 0 | O37: =E37-D37 -> -36
A38: 36 | B38: UC075 | C38: =VLOOKUP(B38,バーコード貼付!$A$1:$D$4652,2,FALSE) -> 軸75TWｼｰﾙｽﾀﾝ用ｶｰﾎﾞﾝﾌﾞﾗｼ(ｾｯﾄ品) | D38: =VLOOKUP(B38,バーコード貼付!$A$1:$D$4652,3,FALSE) -> 81 | E38: =VLOOKUP(B38,バーコード貼付!$A$1:$D$4652,4,FALSE) -> 30 | G38: =IF(D38-E38>=0,0,1) -> 0 | I38: =IF(AND(D38<=0,D38-E38<0),1,0) -> 0 | O38: =E38-D38 -> -51
A39: 37 | B39: CT04085 | C39: =VLOOKUP(B39,バーコード貼付!$A$1:$D$4652,2,FALSE) -> BC85(S140)単式ｽﾀﾝL1*424 | D39: =VLOOKUP(B39,バーコード貼付!$A$1:$D$4652,3,FALSE) -> 1 | E39: 1 | G39: =IF(D39-E39>=0,0,1) -> 0 | I39: =IF(AND(D39<=0,D39-E39<0),1,0) -> 0 | O39: =E39-D39 -> 0
A40: 38 | B40: TO04110 | C40: =VLOOKUP(B40,バーコード貼付!$A$1:$D$4652,2,FALSE) -> BCS170x110TSS型前部ｽﾀﾝﾎﾞｯｸｽ | D40: =VLOOKUP(B40,バーコード貼付!$A$1:$D$4652,3,FALSE) -> 5 | E40: 5 | G40: =IF(D40-E40>=0,0,1) -> 0 | I40: =IF(AND(D40<=0,D40-E40<0),1,0) -> 0 | O40: =E40-D40 -> 0
...

Sheet 4
F1: =TODAY()-90 -> 46203
A2: 番号 | B2: コード | C2: 4.キングストン | D2: 在庫数 | E2: 発注点 | F2: 発注点割れ | G2: =SUM(G3:G110) -> 10 | H2: 在庫欠品 | I2: =SUM(I3:I110) -> 0 | P2: =P1+1 -> 1
A3: 1 | B3: KA91038 | C3: =VLOOKUP(B3,バーコード貼付!$A$1:$D$4652,2,FALSE) -> 38ﾎﾞｰﾙｷﾝｸﾞｽﾄﾝ用ｴﾙﾎﾞﾌﾗﾝｼﾞのみ | D3: =VLOOKUP(B3,バーコード貼付!$A$1:$D$4652,3,FALSE) -> 13 | E3: 17 | F3: 46251 | G3: =IF(D3-E3>=0,0,1) -> 1 | I3: =IF(AND(D3<=0,D3-E3<0),1,0) -> 0 | O3: =E3-D3 -> 4
A4: 2 | B4: KA90050050 | C4: =VLOOKUP(B4,バーコード貼付!$A$1:$D$4652,2,FALSE) -> 50*PT50ｷﾝｸﾞｽﾄﾝ用ねじ込みBCﾌﾗﾝｼﾞ | D4: =VLOOKUP(B4,バーコード貼付!$A$1:$D$4652,3,FALSE) -> 4 | E4: 30 | F4: 46275 | G4: =IF(D4-E4>=0,0,1) -> 1 | I4: =IF(AND(D4<=0,D4-E4<0),1,0) -> 0 | O4: =E4-D4 -> 26
A5: 3 | B5: KA6903225 | C5: =VLOOKUP(B5,バーコード貼付!$A$1:$D$4652,2,FALSE) -> 32*25ﾎﾞｰﾙｷﾝｸﾞｽﾄﾝ用本体(ｴﾙﾎﾞ付) | D5: =VLOOKUP(B5,バーコード貼付!$A$1:$D$4652,3,FALSE) -> 11 | E5: 22 | F5: 46217 | G5: =IF(D5-E5>=0,0,1) -> 1 | I5: =IF(AND(D5<=0,D5-E5<0),1,0) -> 0 | O5: =E5-D5 -> 11
A6: 4 | B6: KA61032ST | C6: =VLOOKUP(B6,バーコード貼付!$A$1:$D$4652,2,FALSE) -> 11/4(32)TA型高速吸水式ｷﾝｸﾞｽﾄﾝ用ﾗｯﾊﾟ | D6: =VLOOKUP(B6,バーコード貼付!$A$1:$D$4652,3,FALSE) -> 96 | E6: 98 | F6: 46224 | G6: =IF(D6-E6>=0,0,1) -> 1 | I6: =IF(AND(D6<=0,D6-E6<0),1,0) -> 0 | O6: =E6-D6 -> 2
A7: 5 | B7: KA63050 | C7: =VLOOKUP(B7,バーコード貼付!$A$1:$D$4652,2,FALSE) -> 2”(50)銅管ﾎﾞｰﾙ型ｷﾝｸﾞｽﾄﾝ用本体 | D7: =VLOOKUP(B7,バーコード貼付!$A$1:$D$4652,3,FALSE) -> 2 | E7: 12 | F7: 46231 | G7: =IF(D7-E7>=0,0,1) -> 1 | I7: =IF(AND(D7<=0,D7-E7<0),1,0) -> 0 | O7: =E7-D7 -> 10
A8: 6 | B8: KA65076 | C8: =VLOOKUP(B8,バーコード貼付!$A$1:$D$4652,2,FALSE) -> 3”(76)ﾎｰｽ配管ﾎﾞｰﾙ型ｷﾝｸﾞｽﾄﾝ用本体 | D8: =VLOOKUP(B8,バーコード貼付!$A$1:$D$4652,3,FALSE) -> 10 | E8: 11 | F8: 46233 | G8: =IF(D8-E8>=0,0,1) -> 1 | I8: =IF(AND(D8<=0,D8-E8<0),1,0) -> 0 | O8: =E8-D8 -> 1
A9: 7 | B9: KA65032 | C9: =VLOOKUP(B9,バーコード貼付!$A$1:$D$4652,2,FALSE) -> 11/4(32)ﾎｰｽ配管ﾎﾞｰﾙ型ｷﾝｸﾞｽﾄﾝ用本体 | D9: =VLOOKUP(B9,バーコード貼付!$A$1:$D$4652,3,FALSE) -> 36 | E9: 59 | F9: 46233 | G9: =IF(D9-E9>=0,0,1) -> 1 | I9: =IF(AND(D9<=0,D9-E9<0),1,0) -> 0 | O9: =E9-D9 -> 23
A10: 8 | B10: KA91050 | C10: =VLOOKUP(B10,バーコード貼付!$A$1:$D$4652,2,FALSE) -> 2”(50)ﾎﾞｰﾙｷﾝｸﾞｽﾄﾝ用ｴﾙﾎﾞﾌﾗﾝｼﾞのみ | D10: =VLOOKUP(B10,バーコード貼付!$A$1:$D$4652,3,FALSE) -> 30 | E10: 31 | F10: 46280 | G10: =IF(D10-E10>=0,0,1) -> 1 | I10: =IF(AND(D10<=0,D10-E10<0),1,0) -> 0 | O10: =E10-D10 -> 1
A11: 9 | B11: KA69076 | C11: =VLOOKUP(B11,バーコード貼付!$A$1:$D$4652,2,FALSE) -> 3”(76)ﾎﾞｰﾙｷﾝｸﾞｽﾄﾝ用本体(ｴﾙﾎﾞ付) | D11: =VLOOKUP(B11,バーコード貼付!$A$1:$D$4652,3,FALSE) -> 16 | E11: =VLOOKUP(B11,バーコード貼付!$A$1:$D$4652,4,FALSE) -> 20 | F11: 46280 | G11: =IF(D11-E11>=0,0,1) -> 1 | I11: =IF(AND(D11<=0,D11-E11<0),1,0) -> 0 | O11: =E11-D11 -> 4
A12: 10 | B12: KA65038 | C12: =VLOOKUP(B12,バーコード貼付!$A$1:$D$4652,2,FALSE) -> 11/2(38)ﾎｰｽ配管ﾎﾞｰﾙ型ｷﾝｸﾞｽﾄﾝ用本体 | D12: =VLOOKUP(B12,バーコード貼付!$A$1:$D$4652,3,FALSE) -> 45 | E12: 49 | F12: 46290 | G12: =IF(D12-E12>=0,0,1) -> 1 | I12: =IF(AND(D12<=0,D12-E12<0),1,0) -> 0 | O12: =E12-D12 -> 4
A13: 11 | B13: KA65050 | C13: =VLOOKUP(B13,バーコード貼付!$A$1:$D$4652,2,FALSE) -> 2”(50)ﾎｰｽ配管ﾎﾞｰﾙ型ｷﾝｸﾞｽﾄﾝ用本体 | D13: =VLOOKUP(B13,バーコード貼付!$A$1:$D$4652,3,FALSE) -> 102 | E13: 86 | G13: =IF(D13-E13>=0,0,1) -> 0 | I13: =IF(AND(D13<=0,D13-E13<0),1,0) -> 0 | O13: =E13-D13 -> -16
A14: 12 | B14: KA69050 | C14: =VLOOKUP(B14,バーコード貼付!$A$1:$D$4652,2,FALSE) -> 2”(50)ﾎﾞｰﾙｷﾝｸﾞｽﾄﾝ用本体(ｴﾙﾎﾞ付) | D14: =VLOOKUP(B14,バーコード貼付!$A$1:$D$4652,3,FALSE) -> 79 | E14: 67 | G14: =IF(D14-E14>=0,0,1) -> 0 | I14: =IF(AND(D14<=0,D14-E14<0),1,0) -> 0 | O14: =E14-D14 -> -12
A15: 13 | B15: KA69065 | C15: =VLOOKUP(B15,バーコード貼付!$A$1:$D$4652,2,FALSE) -> 65ﾎﾞｰﾙｷﾝｸﾞｽﾄﾝ用本体(ｴﾙﾎﾞ付) | D15: =VLOOKUP(B15,バーコード貼付!$A$1:$D$4652,3,FALSE) -> 84 | E15: 33 | G15: =IF(D15-E15>=0,0,1) -> 0 | I15: =IF(AND(D15<=0,D15-E15<0),1,0) -> 0 | O15: =E15-D15 -> -51
A16: 14 | B16: KA89050 | C16: =VLOOKUP(B16,バーコード貼付!$A$1:$D$4652,2,FALSE) -> 2”(50)ﾎﾞｰﾙ型ｷﾝｸﾞｽﾄﾝﾎｰｽ用ﾌﾗﾝｼﾞ | D16: =VLOOKUP(B16,バーコード貼付!$A$1:$D$4652,3,FALSE) -> 11 | E16: =VLOOKUP(B16,バーコード貼付!$A$1:$D$4652,4,FALSE) -> 10 | G16: =IF(D16-E16>=0,0,1) -> 0 | I16: =IF(AND(D16<=0,D16-E16<0),1,0) -> 0 | O16: =E16-D16 -> -1
A17: 15 | B17: KA69038 | C17: =VLOOKUP(B17,バーコード貼付!$A$1:$D$4652,2,FALSE) -> 38ﾎﾞｰﾙｷﾝｸﾞｽﾄﾝ用本体(ｴﾙﾎﾞ付) | D17: =VLOOKUP(B17,バーコード貼付!$A$1:$D$4652,3,FALSE) -> 39 | E17: 36 | G17: =IF(D17-E17>=0,0,1) -> 0 | I17: =IF(AND(D17<=0,D17-E17<0),1,0) -> 0 | O17: =E17-D17 -> -3
A18: 16 | B18: KA89065 | C18: =VLOOKUP(B18,バーコード貼付!$A$1:$D$4652,2,FALSE) -> 65ﾎﾞｰﾙ型ｷﾝｸﾞｽﾄﾝﾎｰｽ用ﾌﾗﾝｼﾞ | D18: =VLOOKUP(B18,バーコード貼付!$A$1:$D$4652,3,FALSE) -> 12 | E18: =VLOOKUP(B18,バーコード貼付!$A$1:$D$4652,4,FALSE) -> 10 | G18: =IF(D18-E18>=0,0,1) -> 0 | I18: =IF(AND(D18<=0,D18-E18<0),1,0) -> 0 | O18: =E18-D18 -> -2
A19: 17 | B19: KA97050AW | C19: =VLOOKUP(B19,バーコード貼付!$A$1:$D$4652,2,FALSE) -> 2”分離型ﾗｯﾊﾟ用網ﾌﾀのみ | D19: =VLOOKUP(B19,バーコード貼付!$A$1:$D$4652,3,FALSE) -> 28 | E19: 3 | G19: =IF(D19-E19>=0,0,1) -> 0 | I19: =IF(AND(D19<=0,D19-E19<0),1,0) -> 0 | O19: =E19-D19 -> -25
A20: 18 | B20: KA97038AW | C20: =VLOOKUP(B20,バーコード貼付!$A$1:$D$4652,2,FALSE) -> 11/2分離型ﾗｯﾊﾟ用網ﾌﾀのみ | D20: =VLOOKUP(B20,バーコード貼付!$A$1:$D$4652,3,FALSE) -> 9 | E20: 2 | G20: =IF(D20-E20>=0,0,1) -> 0 | I20: =IF(AND(D20<=0,D20-E20<0),1,0) -> 0 | O20: =E20-D20 -> -7
A21: 19 | B21: KA9103225 | C21: =VLOOKUP(B21,バーコード貼付!$A$1:$D$4652,2,FALSE) -> 32*25ﾎﾞｰﾙｷﾝｸﾞｽﾄﾝ用ｴﾙﾎﾞﾌﾗﾝｼﾞのみ | D21: =VLOOKUP(B21,バーコード貼付!$A$1:$D$4652,3,FALSE) -> 82 | E21: 8 | G21: =IF(D21-E21>=0,0,1) -> 0 | I21: =IF(AND(D21<=0,D21-E21<0),1,0) -> 0 | O21: =E21-D21 -> -74
A22: 20 | B22: KA97100AW | C22: =VLOOKUP(B22,バーコード貼付!$A$1:$D$4652,2,FALSE) -> 4”分離型ﾗｯﾊﾟ用網ﾌﾀのみ | D22: =VLOOKUP(B22,バーコード貼付!$A$1:$D$4652,3,FALSE) -> 1 | E22: 1 | G22: =IF(D22-E22>=0,0,1) -> 0 | I22: =IF(AND(D22<=0,D22-E22<0),1,0) -> 0 | O22: =E22-D22 -> 0
A23: 21 | B23: KA63065 | C23: =VLOOKUP(B23,バーコード貼付!$A$1:$D$4652,2,FALSE) -> 21/2(65)銅管ﾎﾞｰﾙ型ｷﾝｸﾞｽﾄﾝ用本体 | D23: =VLOOKUP(B23,バーコード貼付!$A$1:$D$4652,3,FALSE) -> 9 | E23: 4 | G23: =IF(D23-E23>=0,0,1) -> 0 | I23: =IF(AND(D23<=0,D23-E23<0),1,0) -> 0 | O23: =E23-D23 -> -5
A24: 22 | B24: KA89038 | C24: =VLOOKUP(B24,バーコード貼付!$A$1:$D$4652,2,FALSE) -> 38ﾎﾞｰﾙ型ｷﾝｸﾞｽﾄﾝﾎｰｽ用ﾌﾗﾝｼﾞ | D24: =VLOOKUP(B24,バーコード貼付!$A$1:$D$4652,3,FALSE) -> 17 | E24: 2 | G24: =IF(D24-E24>=0,0,1) -> 0 | I24: =IF(AND(D24<=0,D24-E24<0),1,0) -> 0 | O24: =E24-D24 -> -15
A25: 23 | B25: KA61038STW | C25: =VLOOKUP(B25,バーコード貼付!$A$1:$D$4652,2,FALSE) -> 38TA型ｷﾝｸﾞｽﾄﾝ用ﾗｯﾊﾟ蓋分離式 | D25: =VLOOKUP(B25,バーコード貼付!$A$1:$D$4652,3,FALSE) -> 224 | E25: =VLOOKUP(B25,バーコード貼付!$A$1:$D$4652,4,FALSE) -> 150 | G25: =IF(D25-E25>=0,0,1) -> 0 | I25: =IF(AND(D25<=0,D25-E25<0),1,0) -> 0 | O25: =E25-D25 -> -74
A26: 24 | B26: KA65065 | C26: =VLOOKUP(B26,バーコード貼付!$A$1:$D$4652,2,FALSE) -> 21/2(65)ﾎｰｽ配管ﾎﾞｰﾙ型ｷﾝｸﾞｽﾄﾝ用本体 | D26: =VLOOKUP(B26,バーコード貼付!$A$1:$D$4652,3,FALSE) -> 92 | E26: 23 | G26: =IF(D26-E26>=0,0,1) -> 0 | I26: =IF(AND(D26<=0,D26-E26<0),1,0) -> 0 | O26: =E26-D26 -> -69
A27: 25 | B27: KA97038AWM | C27: =VLOOKUP(B27,バーコード貼付!$A$1:$D$4652,2,FALSE) -> 11/2分離型ﾗｯﾊﾟ用網ﾌﾀのみ丸穴 | D27: =VLOOKUP(B27,バーコード貼付!$A$1:$D$4652,3,FALSE) -> 57 | E27: 37 | G27: =IF(D27-E27>=0,0,1) -> 0 | I27: =IF(AND(D27<=0,D27-E27<0),1,0) -> 0 | O27: =E27-D27 -> -20
A28: 26 | B28: KA61032STW | C28: =VLOOKUP(B28,バーコード貼付!$A$1:$D$4652,2,FALSE) -> 32TA型ｷﾝｸﾞｽﾄﾝ用ﾗｯﾊﾟ蓋分離式 | D28: =VLOOKUP(B28,バーコード貼付!$A$1:$D$4652,3,FALSE) -> 258 | E28: =VLOOKUP(B28,バーコード貼付!$A$1:$D$4652,4,FALSE) -> 80 | G28: =IF(D28-E28>=0,0,1) -> 0 | I28: =IF(AND(D28<=0,D28-E28<0),1,0) -> 0 | O28: =E28-D28 -> -178
A29: 27 | B29: KA63032 | C29: =VLOOKUP(B29,バーコード貼付!$A$1:$D$4652,2,FALSE) -> 11/4(32)銅管ﾎﾞｰﾙ型ｷﾝｸﾞｽﾄﾝ用本体 | D29: =VLOOKUP(B29,バーコード貼付!$A$1:$D$4652,3,FALSE) -> 1 | E29: 1 | G29: =IF(D29-E29>=0,0,1) -> 0 | I29: =IF(AND(D29<=0,D29-E29<0),1,0) -> 0 | O29: =E29-D29 -> 0
A30: 28 | B30: KA69045 | C30: =VLOOKUP(B30,バーコード貼付!$A$1:$D$4652,2,FALSE) -> 45ﾎﾞｰﾙｷﾝｸﾞｽﾄﾝ用本体(ｴﾙﾎﾞ付) | D30: =VLOOKUP(B30,バーコード貼付!$A$1:$D$4652,3,FALSE) -> 22 | E30: 1 | G30: =IF(D30-E30>=0,0,1) -> 0 | I30: =IF(AND(D30<=0,D30-E30<0),1,0) -> 0 | O30: =E30-D30 -> -21
A31: 29 | B31: KA89076 | C31: =VLOOKUP(B31,バーコード貼付!$A$1:$D$4652,2,FALSE) -> 3”(76)ﾎﾞｰﾙ型ｷﾝｸﾞｽﾄﾝﾎｰｽ用ﾌﾗﾝｼﾞ | D31: =VLOOKUP(B31,バーコード貼付!$A$1:$D$4652,3,FALSE) -> 85 | E31: 5 | G31: =IF(D31-E31>=0,0,1) -> 0 | I31: =IF(AND(D31<=0,D31-E31<0),1,0) -> 0 | O31: =E31-D31 -> -80
A32: 30 | B32: KA8903225 | C32: =VLOOKUP(B32,バーコード貼付!$A$1:$D$4652,2,FALSE) -> 32X25ﾎﾞｰﾙ型ｷﾝｸﾞｽﾄﾝﾎｰｽ用ﾌﾗﾝｼﾞ | D32: =VLOOKUP(B32,バーコード貼付!$A$1:$D$4652,3,FALSE) -> 2 | E32: 2 | G32: =IF(D32-E32>=0,0,1) -> 0 | I32: =IF(AND(D32<=0,D32-E32<0),1,0) -> 0 | O32: =E32-D32 -> 0
A33: 31 | B33: KA91065 | C33: =VLOOKUP(B33,バーコード貼付!$A$1:$D$4652,2,FALSE) -> 65ﾎﾞｰﾙｷﾝｸﾞｽﾄﾝ用ｴﾙﾎﾞﾌﾗﾝｼﾞのみ | D33: =VLOOKUP(B33,バーコード貼付!$A$1:$D$4652,3,FALSE) -> 44 | E33: 34 | G33: =IF(D33-E33>=0,0,1) -> 0 | I33: =IF(AND(D33<=0,D33-E33<0),1,0) -> 0 | O33: =E33-D33 -> -10
A34: 32 | B34: KA97076AWM | C34: =VLOOKUP(B34,バーコード貼付!$A$1:$D$4652,2,FALSE) -> 3”分離型ﾗｯﾊﾟ用網ﾌﾀのみ丸穴 | D34: =VLOOKUP(B34,バーコード貼付!$A$1:$D$4652,3,FALSE) -> 94 | E34: 16 | G34: =IF(D34-E34>=0,0,1) -> 0 | I34: =IF(AND(D34<=0,D34-E34<0),1,0) -> 0 | O34: =E34-D34 -> -78
A35: 33 | B35: KA61050STW | C35: =VLOOKUP(B35,バーコード貼付!$A$1:$D$4652,2,FALSE) -> 50TA型ｷﾝｸﾞｽﾄﾝ用ﾗｯﾊﾟ蓋分離式 | D35: =VLOOKUP(B35,バーコード貼付!$A$1:$D$4652,3,FALSE) -> 220 | E35: =VLOOKUP(B35,バーコード貼付!$A$1:$D$4652,4,FALSE) -> 150 | G35: =IF(D35-E35>=0,0,1) -> 0 | I35: =IF(AND(D35<=0,D35-E35<0),1,0) -> 0 | O35: =E35-D35 -> -70
A36: 34 | B36: KA90100100 | C36: =VLOOKUP(B36,バーコード貼付!$A$1:$D$4652,2,FALSE) -> 100*PT100ｷﾝｸﾞｽﾄﾝ用ねじ込みBCﾌﾗﾝｼﾞ | D36: =VLOOKUP(B36,バーコード貼付!$A$1:$D$4652,3,FALSE) -> 58 | E36: =VLOOKUP(B36,バーコード貼付!$A$1:$D$4652,4,FALSE) -> 5 | G36: =IF(D36-E36>=0,0,1) -> 0 | I36: =IF(AND(D36<=0,D36-E36<0),1,0) -> 0 | O36: =E36-D36 -> -53
A37: 35 | B37: KA97050AWM | C37: =VLOOKUP(B37,バーコード貼付!$A$1:$D$4652,2,FALSE) -> 2”分離型ﾗｯﾊﾟ用網ﾌﾀのみ丸穴 | D37: =VLOOKUP(B37,バーコード貼付!$A$1:$D$4652,3,FALSE) -> 279 | E37: =VLOOKUP(B37,バーコード貼付!$A$1:$D$4652,4,FALSE) -> 100 | G37: =IF(D37-E37>=0,0,1) -> 0 | I37: =IF(AND(D37<=0,D37-E37<0),1,0) -> 0 | O37: =E37-D37 -> -179
A38: 36 | B38: KA90038038 | C38: =VLOOKUP(B38,バーコード貼付!$A$1:$D$4652,2,FALSE) -> 38*PT38ｷﾝｸﾞｽﾄﾝ用ねじ込みBCﾌﾗﾝｼﾞ | D38: =VLOOKUP(B38,バーコード貼付!$A$1:$D$4652,3,FALSE) -> 26 | E38: =VLOOKUP(B38,バーコード貼付!$A$1:$D$4652,4,FALSE) -> 25 | G38: =IF(D38-E38>=0,0,1) -> 0 | I38: =IF(AND(D38<=0,D38-E38<0),1,0) -> 0 | O38: =E38-D38 -> -1
A39: 37 | B39: KA97065W | C39: =VLOOKUP(B39,バーコード貼付!$A$1:$D$4652,2,FALSE) -> 65ｽｰﾊﾟｰｷﾝｸﾞｽﾄﾝ用ﾗｯﾊﾟ部蓋分離式 | D39: =VLOOKUP(B39,バーコード貼付!$A$1:$D$4652,3,FALSE) -> 228 | E39: =VLOOKUP(B39,バーコード貼付!$A$1:$D$4652,4,FALSE) -> 50 | G39: =IF(D39-E39>=0,0,1) -> 0 | I39: =IF(AND(D39<=0,D39-E39<0),1,0) -> 0 | O39: =E39-D39 -> -178
A40: 38 | B40: KA97038W | C40: =VLOOKUP(B40,バーコード貼付!$A$1:$D$4652,2,FALSE) -> 38ｽｰﾊﾟｰｷﾝｸﾞｽﾄﾝ用ﾗｯﾊﾟ部蓋分離式 | D40: =VLOOKUP(B40,バーコード貼付!$A$1:$D$4652,3,FALSE) -> 137 | E40: =VLOOKUP(B40,バーコード貼付!$A$1:$D$4652,4,FALSE) -> 70 | G40: =IF(D40-E40>=0,0,1) -> 0 | I40: =IF(AND(D40<=0,D40-E40<0),1,0) -> 0 | O40: =E40-D40 -> -67
...

Sheet 5
F1: =TODAY()-90 -> 46203
A2: 番号 | B2: コード | C2: 5.シール類 | D2: 在庫数 | E2: 発注点 | F2: 発注点割れ | G2: =SUM(G3:G19) -> 2 | H2: 在庫欠品 | I2: =SUM(I3:I19) -> 0 | P2: =P1+1 -> 1
A3: 1 | B3: TQ09050 | C3: =VLOOKUP(B3,バーコード貼付!$A$1:$D$4652,2,FALSE) -> 50ｼｰﾙｽﾀﾝ用ﾀﾞｲﾔﾌﾗﾑ | D3: =VLOOKUP(B3,バーコード貼付!$A$1:$D$4652,3,FALSE) -> 17 | E3: =VLOOKUP(B3,バーコード貼付!$A$1:$D$4652,4,FALSE) -> 30 | F3: 46259 | G3: =IF(D3-E3>=0,0,1) -> 1 | I3: =IF(AND(D3<=0,D3-E3<0),1,0) -> 0 | O3: =E3-D3 -> 13
A4: 2 | B4: TQ09065 | C4: =VLOOKUP(B4,バーコード貼付!$A$1:$D$4652,2,FALSE) -> 65ｼｰﾙｽﾀﾝ用ﾀﾞｲﾔﾌﾗﾑ | D4: =VLOOKUP(B4,バーコード貼付!$A$1:$D$4652,3,FALSE) -> 26 | E4: =VLOOKUP(B4,バーコード貼付!$A$1:$D$4652,4,FALSE) -> 30 | F4: 46274 | G4: =IF(D4-E4>=0,0,1) -> 1 | I4: =IF(AND(D4<=0,D4-E4<0),1,0) -> 0 | O4: =E4-D4 -> 4
A5: 3 | B5: TQ09070 | C5: =VLOOKUP(B5,バーコード貼付!$A$1:$D$4652,2,FALSE) -> 70ｼｰﾙｽﾀﾝ用ﾀﾞｲﾔﾌﾗﾑ | D5: =VLOOKUP(B5,バーコード貼付!$A$1:$D$4652,3,FALSE) -> 37 | E5: =VLOOKUP(B5,バーコード貼付!$A$1:$D$4652,4,FALSE) -> 30 | G5: =IF(D5-E5>=0,0,1) -> 0 | I5: =IF(AND(D5<=0,D5-E5<0),1,0) -> 0 | O5: =E5-D5 -> -7
A6: 4 | B6: TQ09055 | C6: =VLOOKUP(B6,バーコード貼付!$A$1:$D$4652,2,FALSE) -> 55ｼｰﾙｽﾀﾝ用ﾀﾞｲﾔﾌﾗﾑ | D6: =VLOOKUP(B6,バーコード貼付!$A$1:$D$4652,3,FALSE) -> 29 | E6: 15 | G6: =IF(D6-E6>=0,0,1) -> 0 | I6: =IF(AND(D6<=0,D6-E6<0),1,0) -> 0 | O6: =E6-D6 -> -14
A7: 5 | B7: TQ09075 | C7: =VLOOKUP(B7,バーコード貼付!$A$1:$D$4652,2,FALSE) -> 75ｼｰﾙｽﾀﾝ用ﾀﾞｲﾔﾌﾗﾑ | D7: =VLOOKUP(B7,バーコード貼付!$A$1:$D$4652,3,FALSE) -> 40 | E7: =VLOOKUP(B7,バーコード貼付!$A$1:$D$4652,4,FALSE) -> 30 | G7: =IF(D7-E7>=0,0,1) -> 0 | I7: =IF(AND(D7<=0,D7-E7<0),1,0) -> 0 | O7: =E7-D7 -> -10
A8: 6 | B8: TQ09040 | C8: =VLOOKUP(B8,バーコード貼付!$A$1:$D$4652,2,FALSE) -> 40ｼｰﾙｽﾀﾝ用ﾀﾞｲﾔﾌﾗﾑ | D8: =VLOOKUP(B8,バーコード貼付!$A$1:$D$4652,3,FALSE) -> 31 | E8: 15 | G8: =IF(D8-E8>=0,0,1) -> 0 | I8: =IF(AND(D8<=0,D8-E8<0),1,0) -> 0 | O8: =E8-D8 -> -16
A9: 7 | B9: TQ09060 | C9: =VLOOKUP(B9,バーコード貼付!$A$1:$D$4652,2,FALSE) -> 60ｼｰﾙｽﾀﾝ用ﾀﾞｲﾔﾌﾗﾑ | D9: =VLOOKUP(B9,バーコード貼付!$A$1:$D$4652,3,FALSE) -> 31 | E9: =VLOOKUP(B9,バーコード貼付!$A$1:$D$4652,4,FALSE) -> 30 | G9: =IF(D9-E9>=0,0,1) -> 0 | I9: =IF(AND(D9<=0,D9-E9<0),1,0) -> 0 | O9: =E9-D9 -> -1
A10: 8 | B10: TQ09110 | C10: =VLOOKUP(B10,バーコード貼付!$A$1:$D$4652,2,FALSE) -> 110ｼｰﾙｽﾀﾝ用ﾀﾞｲﾔﾌﾗﾑ | D10: =VLOOKUP(B10,バーコード貼付!$A$1:$D$4652,3,FALSE) -> 23 | E10: 13 | G10: =IF(D10-E10>=0,0,1) -> 0 | I10: =IF(AND(D10<=0,D10-E10<0),1,0) -> 0 | O10: =E10-D10 -> -10
A11: 9 | B11: TSL22130 | C11: =VLOOKUP(B11,バーコード貼付!$A$1:$D$4652,2,FALSE) -> TSL-1302型ﾀﾞｲﾔﾌﾗﾑ | D11: =VLOOKUP(B11,バーコード貼付!$A$1:$D$4652,3,FALSE) -> 18 | E11: 10 | G11: =IF(D11-E11>=0,0,1) -> 0 | I11: =IF(AND(D11<=0,D11-E11<0),1,0) -> 0 | O11: =E11-D11 -> -8
A12: 10 | B12: TSL22120 | C12: =VLOOKUP(B12,バーコード貼付!$A$1:$D$4652,2,FALSE) -> TSL-1202型ﾀﾞｲﾔﾌﾗﾑ | D12: =VLOOKUP(B12,バーコード貼付!$A$1:$D$4652,3,FALSE) -> 17 | E12: 9 | G12: =IF(D12-E12>=0,0,1) -> 0 | I12: =IF(AND(D12<=0,D12-E12<0),1,0) -> 0 | O12: =E12-D12 -> -8
A13: 11 | B13: TQ09045 | C13: =VLOOKUP(B13,バーコード貼付!$A$1:$D$4652,2,FALSE) -> 45ｼｰﾙｽﾀﾝ用ﾀﾞｲﾔﾌﾗﾑ | D13: =VLOOKUP(B13,バーコード貼付!$A$1:$D$4652,3,FALSE) -> 20 | E13: 9 | G13: =IF(D13-E13>=0,0,1) -> 0 | I13: =IF(AND(D13<=0,D13-E13<0),1,0) -> 0 | O13: =E13-D13 -> -11
A14: 12 | B14: TQ09085 | C14: =VLOOKUP(B14,バーコード貼付!$A$1:$D$4652,2,FALSE) -> 85ｼｰﾙｽﾀﾝ用ﾀﾞｲﾔﾌﾗﾑ | D14: =VLOOKUP(B14,バーコード貼付!$A$1:$D$4652,3,FALSE) -> 14 | E14: 8 | G14: =IF(D14-E14>=0,0,1) -> 0 | I14: =IF(AND(D14<=0,D14-E14<0),1,0) -> 0 | O14: =E14-D14 -> -6
A15: 13 | B15: TQ09080 | C15: =VLOOKUP(B15,バーコード貼付!$A$1:$D$4652,2,FALSE) -> 80ｼｰﾙｽﾀﾝ用ﾀﾞｲﾔﾌﾗﾑ | D15: =VLOOKUP(B15,バーコード貼付!$A$1:$D$4652,3,FALSE) -> 15 | E15: 5 | G15: =IF(D15-E15>=0,0,1) -> 0 | I15: =IF(AND(D15<=0,D15-E15<0),1,0) -> 0 | O15: =E15-D15 -> -10
A16: 14 | B16: TQ09095 | C16: =VLOOKUP(B16,バーコード貼付!$A$1:$D$4652,2,FALSE) -> 95ｼｰﾙｽﾀﾝ用ﾀﾞｲﾔﾌﾗﾑ | D16: =VLOOKUP(B16,バーコード貼付!$A$1:$D$4652,3,FALSE) -> 21 | E16: 9 | G16: =IF(D16-E16>=0,0,1) -> 0 | I16: =IF(AND(D16<=0,D16-E16<0),1,0) -> 0 | O16: =E16-D16 -> -12
A17: 15 | B17: TQ09100 | C17: =VLOOKUP(B17,バーコード貼付!$A$1:$D$4652,2,FALSE) -> 100ｼｰﾙｽﾀﾝ用ﾀﾞｲﾔﾌﾗﾑ | D17: =VLOOKUP(B17,バーコード貼付!$A$1:$D$4652,3,FALSE) -> 14 | E17: 5 | G17: =IF(D17-E17>=0,0,1) -> 0 | I17: =IF(AND(D17<=0,D17-E17<0),1,0) -> 0 | O17: =E17-D17 -> -9
A18: 16 | B18: TQ09090 | C18: =VLOOKUP(B18,バーコード貼付!$A$1:$D$4652,2,FALSE) -> 90ｼｰﾙｽﾀﾝ用ﾀﾞｲﾔﾌﾗﾑ | D18: =VLOOKUP(B18,バーコード貼付!$A$1:$D$4652,3,FALSE) -> 30 | E18: 8 | G18: =IF(D18-E18>=0,0,1) -> 0 | I18: =IF(AND(D18<=0,D18-E18<0),1,0) -> 0 | O18: =E18-D18 -> -22
A19: 17 | B19: TQ09105 | C19: =VLOOKUP(B19,バーコード貼付!$A$1:$D$4652,2,FALSE) -> 105ｼｰﾙｽﾀﾝ用ﾀﾞｲﾔﾌﾗﾑ | D19: =VLOOKUP(B19,バーコード貼付!$A$1:$D$4652,3,FALSE) -> 26 | E19: 7 | G19: =IF(D19-E19>=0,0,1) -> 0 | I19: =IF(AND(D19<=0,D19-E19<0),1,0) -> 0 | O19: =E19-D19 -> -19

Sheet 6
F1: =TODAY()-90 -> 46203
A2: 番号 | B2: コード | C2: 6.海水コシ器 | D2: 在庫数 | E2: 発注点 | F2: 発注点割れ | G2: =SUM(G3:G45) -> 13 | H2: 在庫欠品 | I2: =SUM(I3:I45) -> 0 | P2: =P1+1 -> 1
A3: 1 | B3: 40SPFNASI | C3: =VLOOKUP(B3,バーコード貼付!$A$1:$D$4652,2,FALSE) -> 40SPﾌﾗﾝｼﾞ型海水こし器(ﾌﾗﾝｼﾞ無し) | D3: =VLOOKUP(B3,バーコード貼付!$A$1:$D$4652,3,FALSE) -> 33 | E3: =VLOOKUP(B3,バーコード貼付!$A$1:$D$4652,4,FALSE) -> 57 | F3: 11/21 | G3: =IF(D3-E3>=0,0,1) -> 1 | I3: =IF(AND(D3<=0,D3-E3<0),1,0) -> 0 | O3: =E3-D3 -> 24
A4: 2 | B4: BN114041SPH | C4: =VLOOKUP(B4,バーコード貼付!$A$1:$D$4652,2,FALSE) -> 40SPH海水こし器用ﾌﾗﾝｼﾞ(41φﾎｰｽ用) | D4: =VLOOKUP(B4,バーコード貼付!$A$1:$D$4652,3,FALSE) -> 0 | E4: 0 | G4: =IF(D4-E4>=0,0,1) -> 0 | I4: =IF(AND(D4<=0,D4-E4<0),1,0) -> 0 | O4: =E4-D4 -> 0
A5: 3 | B5: 80SP | C5: =VLOOKUP(B5,バーコード貼付!$A$1:$D$4652,2,FALSE) -> 80SPﾌﾗﾝｼﾞ型海水こし器 | D5: =VLOOKUP(B5,バーコード貼付!$A$1:$D$4652,3,FALSE) -> 9 | E5: 42 | F5: 46283 | G5: =IF(D5-E5>=0,0,1) -> 1 | I5: =IF(AND(D5<=0,D5-E5<0),1,0) -> 0 | O5: =E5-D5 -> 33
A6: 4 | B6: 80SPH63 | C6: =VLOOKUP(B6,バーコード貼付!$A$1:$D$4652,2,FALSE) -> 80SPH(ﾎｰｽ径63)ﾌﾗﾝｼﾞ型ﾎｰｽ海水こし器 | D6: =VLOOKUP(B6,バーコード貼付!$A$1:$D$4652,3,FALSE) -> 25 | E6: 50 | F6: 46237 | G6: =IF(D6-E6>=0,0,1) -> 1 | I6: =IF(AND(D6<=0,D6-E6<0),1,0) -> 0 | O6: =E6-D6 -> 25
A7: 5 | B7: 50SPH50 | C7: =VLOOKUP(B7,バーコード貼付!$A$1:$D$4652,2,FALSE) -> 50SPH(ﾎｰｽ径50)ﾌﾗﾝｼﾞ型ﾎｰｽ海水こし器 | D7: =VLOOKUP(B7,バーコード貼付!$A$1:$D$4652,3,FALSE) -> 4 | E7: 21 | F7: 46253 | G7: =IF(D7-E7>=0,0,1) -> 1 | I7: =IF(AND(D7<=0,D7-E7<0),1,0) -> 0 | O7: =E7-D7 -> 17
A8: 6 | B8: BN113225SPH | C8: =VLOOKUP(B8,バーコード貼付!$A$1:$D$4652,2,FALSE) -> 32SPH海水こし器用ﾌﾗﾝｼﾞ(25φﾎｰｽ用) | D8: =VLOOKUP(B8,バーコード貼付!$A$1:$D$4652,3,FALSE) -> 14 | E8: =VLOOKUP(B8,バーコード貼付!$A$1:$D$4652,4,FALSE) -> 20 | F8: 46255 | G8: =IF(D8-E8>=0,0,1) -> 1 | I8: =IF(AND(D8<=0,D8-E8<0),1,0) -> 0 | O8: =E8-D8 -> 6
A9: 7 | B9: 38SH | C9: =VLOOKUP(B9,バーコード貼付!$A$1:$D$4652,2,FALSE) -> 38SH一体型ﾎｰｽ用海水こし器 | D9: =VLOOKUP(B9,バーコード貼付!$A$1:$D$4652,3,FALSE) -> 81 | E9: 98 | F9: 46262 | G9: =IF(D9-E9>=0,0,1) -> 1 | I9: =IF(AND(D9<=0,D9-E9<0),1,0) -> 0 | O9: =E9-D9 -> 17
A10: 8 | B10: 50SH | C10: =VLOOKUP(B10,バーコード貼付!$A$1:$D$4652,2,FALSE) -> 50SH一体型ﾎｰｽ用海水こし器 | D10: =VLOOKUP(B10,バーコード貼付!$A$1:$D$4652,3,FALSE) -> 15 | E10: 31 | F10: 46269 | G10: =IF(D10-E10>=0,0,1) -> 1 | I10: =IF(AND(D10<=0,D10-E10<0),1,0) -> 0 | O10: =E10-D10 -> 16
A11: 9 | B11: BN2025SH | C11: =VLOOKUP(B11,バーコード貼付!$A$1:$D$4652,2,FALSE) -> 25SH海水こし器用防蝕亜鉛25x30 | D11: =VLOOKUP(B11,バーコード貼付!$A$1:$D$4652,3,FALSE) -> 176 | E11: =VLOOKUP(B11,バーコード貼付!$A$1:$D$4652,4,FALSE) -> 200 | F11: 46269 | G11: =IF(D11-E11>=0,0,1) -> 1 | I11: =IF(AND(D11<=0,D11-E11<0),1,0) -> 0 | O11: =E11-D11 -> 24
A12: 10 | B12: 40SPH38 | C12: =VLOOKUP(B12,バーコード貼付!$A$1:$D$4652,2,FALSE) -> 40SPH(ﾎｰｽ径38)ﾌﾗﾝｼﾞ型ﾎｰｽ海水こし器 | D12: =VLOOKUP(B12,バーコード貼付!$A$1:$D$4652,3,FALSE) -> 5 | E12: 9 | F12: 46273 | G12: =IF(D12-E12>=0,0,1) -> 1 | I12: =IF(AND(D12<=0,D12-E12<0),1,0) -> 0 | O12: =E12-D12 -> 4
A13: 11 | B13: 32SPH32 | C13: =VLOOKUP(B13,バーコード貼付!$A$1:$D$4652,2,FALSE) -> 32SPH(ﾎｰｽ径32)ﾌﾗﾝｼﾞ型ﾎｰｽ海水こし器 | D13: =VLOOKUP(B13,バーコード貼付!$A$1:$D$4652,3,FALSE) -> 7 | E13: 10 | F13: 46279 | G13: =IF(D13-E13>=0,0,1) -> 1 | I13: =IF(AND(D13<=0,D13-E13<0),1,0) -> 0 | O13: =E13-D13 -> 3
