Workbook

Sheet サマリー
A1: 在庫チェックRPA統合化プロジェクト 拠点別変数表 サマリー
A2: 最終更新：2026年7月6日／企画室 天野
A4: ■ 対象拠点(拠点別設定値シートに全9行、9拠点とも共通ループで実行)
A5: 拠点コード | B5: 拠点名 | C5: 稼働フラグ | D5: 処理シート範囲 | E5: 発注点リセット基準日確認
A6: Z1901 | B6: 札幌 | C6: 有 | D6: 1〜19 | E6: 実ファイル確認済み
A7: Z3932 | B7: 倉庫(本社) | C7: 有 | D7: 1〜20 | E7: 実ファイル確認済み
A8: Z3951 | B8: 製造(大型) | C8: 有 | D8: 1〜8 | E8: 実ファイル確認済み
A9: Z3934 | B9: 外注鉄 | C9: 有 | D9: 1〜27 | E9: 実ファイル確認済み
A10: Z1915 | B10: 船舶(機械部) | C10: 有 | D10: 1〜25 | E10: 実ファイル確認済み
A11: Z1903 | B11: 仙台 | C11: 有 | D11: 1〜18 | E11: 実ファイル確認済み
A12: Z1907 | B12: 福岡 | C12: 有 | D12: 1〜19 | E12: 未確認(PDFのみ)
A13: Z1905 | B13: 東京 | C13: 有 | D13: 1〜19 | E13: 実ファイル確認済み
A14: Z3934 | B14: 成果連絡表(色物) | C14: 有(2026/7/3時点、共有フォルダで本日更新を確認済み) | D14: 1〜18 | E14: 未確認(要現物確認)
A15: ■ 2026/7/6 設計確定：成果連絡表(色物)は9拠点目として統合
A16: 成果連絡表(色物)は拠点別設定値シートの9行目(拠点コード=Z3934/成果連絡表(色物))に統合し、他8拠点と同じ共通ループで実行する。以前記録していた「統合は見送り」は別シナリオとの混同であったため訂正(2026/7/6)。副CSV要否などの拠点固有差異は「CSVデータセット数」「副CSVファイル名」の有無によるデータドリブン判定で吸収し、個別の特別処理は設けない設計とする。 2026/7/6 「拠点ループ対象」列は廃止し、先頭列に新設した「処理有無」列(テスト・保留パラメータ管理用の可変スイッチ)に役割を一本化した。
A18: ■ 要確認事項シート ステータス集計
A19: 未確認 | B19: 14件
A20: 決定済み | B20: 22件
A21: 確認済み・再評価等 | B21: 8件
A22: 回答待ち(暫定反映) | B22: 0件
A23: 合計 | B23: 44件
A25: ■ 荘田室長への最優先確認事項(未回答分)
A26: ・東京：シートループ回数と実部署数の不一致は「業務的な未整備状態(バグではない)」と整理 → 統合版では処理対象シート_終了番号を19に是正済み
A27: ・東京：実際に現在も稼働しているか(ローカルPC側)は未確認のまま。運用実態の直接確認が望ましい。 ※2026/7/6 シナリオPDF確認で判明した「特定ユーザー(ts226010)のパスをハードコードしている」問題自体は、2026/7/6 天野決定により{UserDeskTopPath}変数への統一＋デスクトップ配下の運用配置で解消済み（要確認事項#30 決定済み）。稼働可否そのものの確認（実ファイル更新停滞・稼働フラグ「無」の件、#35・#37参照）は別途継続。
A28: ・福岡：発注点リセット基準日数(部署別)が実ファイル未入手のため未確認
A29: ・仙台：19枚目シート(異常データ)がループ対象外である理由 → 2026/7/6 決定：終了番号が実在シート数より小さい場合は単なるスキップでよいという一般ルールが確定し、仙台は終了番号=18のままでよいことが確定
A31: ■ 2026/7/6 荘田室長より正式回答受領（確定）
A32: ・①外注鉄O列(発注点-在庫数差分)の転記先 → 確定：問題なし(各拠点共通処理化)。規定日数超過時に差分を発注点へ書き換え、発注点を引き下げる業務ロジックと判明
A33: ・②発注点リセット基準日数のシート単位管理方式 → 確定：問題なし(便利)。仕入れリードタイム変更等でシート単位に基準日数を変えて運用してきた実績あり
A34: ・③仙台のシート数19とループ回数18の不一致 → 確定：OK(対象コード消滅シートを空回りさせないため可変ループでよい) (終了番号<実在シート数の場合は単なるスキップ、終了番号>実在シート数の場合はエラーとする一般ルールを別途確定。仙台は前者に該当)
A35: ・④外注鉄／成果連絡表(色物)の日付重複(=TODAY()と確定値) → ★想定と相違：設計ではなくコピー時の消し忘れの可能性大。実害なければどちらか一方を削除する方針に変更
A36: ・⑤外注鉄3シートのコピペ形式(すべて→値のみ) → 確定：値のみコピーで統一してよい
A37: ※2026/7/6 荘田室長より正式回答受領済み。①②③⑤は想定通り確定。④のみ想定と異なり、実装方針を修正(重複列のどちらかを削除)。
... A48: 9拠点統合が完了する前に、実行時間の実測値をもとにスケジュール設計を確定させる必要がある。

Sheet 拠点別設定値
A1: 在庫チェックRPA統合版 拠点別設定値テーブル（このシートを統合シナリオが参照する）
A2: 基本情報 | AY2: 稼働管理 | BA2: 処理対象シート範囲 | BG2: 格納フォルダ管理
A3: 処理有無 | B3: 処理有無_備考 | C3: 拠点コード | D3: 拠点名 | E3: TIMS起動引数 | F3: CSVファイル名 | G3: 在庫帳ブック名 | H3: 参照元(ネットワーク)フルパス | I3: 保存先(ネットワーク)フルパス | J3: 欠品_列挿入位置 | K3: 欠品_コピペ元列 | L3: 欠品_コピペ先列 | M3: 欠品_処理開始行 | N3: 欠品_処理終了行 | O3: 在庫額_列挿入位置 | P3: 在庫額_コピペ元列 | Q3: 在庫額_コピペ先列 | R3: 在庫額_処理開始行 | S3: 在庫額_処理終了行 | T3: CSV範囲_終端列 | U3: CSV範囲_終端行 | V3: シートループ回数 | W3: 休日判定_実行 | X3: ネット事前取得_実行 | Y3: OLDバックアップ_実行 | Z3: CSV空白除去_実行 | AA3: 発注点補正_実行 | AB3: O列転記_実行 | AC3: 追加終了プロセス_実行 | AD3: 追加終了プロセス名 | AE3: CSVデータセット数 | AF3: 副拠点コード | AG3: 副TIMS起動引数 | AH3: 副CSVファイル名 | AI3: 主CSV貼付開始セル | AJ3: 副CSV貼付開始セル | AK3: 副CSV範囲_終端行 | AL3: 欠品色_列挿入位置 | AM3: 欠品色_コピペ元列 | AN3: 欠品色_コピペ先列 | AO3: 欠品色_処理開始行 | AP3: 欠品色_処理終了行 | AQ3: 在庫額色_列挿入位置 | AR3: 在庫額色_コピペ元列 | AS3: 在庫額色_コピペ先列 | AT3: 在庫額色_処理開始行 | AU3: 在庫額色_処理終了行 | AV3: 発注点リセット_実行 | AW3: 発注点リセット_管理方式 | AX3: 発注点リセット_設定参照先 | AY3: 稼働フラグ | AZ3: RPAシナリオ本体_フルパス | BA3: 処理対象シート_開始番号 | BB3: 処理対象シート_終了番号 | BC3: 欠品シート名 | BD3: 在庫額シート名 | BE3: 欠品色シート名 | BF3: 在庫額色シート名 | BG3: 在庫帳ブックローカルフォルダ名
A4: 有 | C4: Z1901 | D4: 札幌 | E4: -site:"Z1901" | F4: 札幌在庫データ.csv | G4: 札幌在庫帳.xlsx | H4: \\192.168.0.35\disk\企画室\倉庫\前日データ\札幌在庫帳.xlsx | I4: \\192.168.0.35\disk\企画室\倉庫 | J4: 23 | K4: X | L4: W | M4: 27 | N4: 48 | O4: 21 | P4: V | Q4: U | R4: 29 | S4: 52 | T4: D | U4: 2000 | V4: 19 | W4: 無 | X4: 無 | Y4: 無 | Z4: 有(統合版で新規実装要・現行札幌シナリオには無し) | AA4: 有 | AB4: 無 | AC4: 無 | AE4: 1 | AI4: A3 | AV4: 有 | AW4: 部署別テーブル参照 | AX4: 発注点リセット_部署別設定シート | AY4: 有 | BA4: 1 | BB4: 19 | BC4: 欠品 | BD4: 在庫額 | BG4: 在庫帳
A5: 有 | C5: Z3932 | D5: 倉庫(本社) | E5: -site:"Z3932" | F5: 倉庫在庫データ.csv | G5: 本社商品在庫日報.xlsx | H5: \\192.168.0.35\disk\企画室\倉庫\前日データ\本社商品在庫日報.xlsx | I5: \\192.168.0.35\disk\企画室\倉庫 | J5: 24 | K5: Y | L5: X | M5: 37 | N5: 58 | O5: 20 | P5: U | Q5: T | R5: 37 | S5: 60 | T5: D | U5: 5000 | V5: 20 | W5: 有 | X5: 有 | Y5: 有 | Z5: 有(PowerShell方式) | AA5: 有 | AB5: 無 | AC5: 有 | AD5: TIMS_C05_InvntInq.exe | AE5: 1 | AI5: A3 | AV5: 有 | AW5: 部署別テーブル参照 | AX5: 発注点リセット_部署別設定シート | AY5: 有 | BA5: 1 | BB5: 20 | BC5: 欠品 | BD5: 在庫額 | BG5: 在庫帳
A6: 有 | C6: Z3951 | D6: 製造(大型) | E6: -site:"Z3951" | F6: 製造在庫データ.csv | G6: 製造在庫帳（大型）.xlsx | H6: \\192.168.0.35\disk\企画室\倉庫\前日データ\製造在庫帳（大型）.xlsx | I6: \\192.168.0.35\disk\企画室\倉庫 | J6: 29 | K6: AD | L6: AC | M6: 37 | N6: 47 | O6: 26 | P6: AA | Q6: Z | R6: 37 | S6: 48 | T6: D | U6: 2000 | V6: 9 | W6: 有 | X6: 有 | Y6: 無※要確認 | Z6: 有(PowerShell方式) | AA6: 有 | AB6: 有 | AC6: 有 | AD6: TIMS_C05_InvntInq.exe | AE6: 1 | AI6: A3 | AV6: 有 | AW6: 部署別テーブル参照 | AX6: 発注点リセット_部署別設定シート | AY6: 有 | BA6: 1 | BB6: 9 | BC6: 欠品 | BD6: 在庫額 | BG6: 在庫帳
A7: 有 | C7: Z3934 | D7: 外注鉄 | E7: -site:"Z3934" | F7: 外注在庫データ.csv | G7: 外注鉄在庫帳.xlsx | H7: \\192.168.0.35\disk\企画室\倉庫\前日データ\外注鉄在庫帳.xlsx | I7: \\192.168.0.35\disk\企画室\倉庫 | J7: 22 | K7: W | L7: V | M7: 27 | N7: 36 | O7: 21 | P7: V | Q7: U | R7: 28 | S7: 39 | T7: D | U7: 4000 | V7: 27 | W7: 無 | X7: 有 | Y7: 無※資料上確認できず | Z7: 有(PowerShell方式) | AA7: 有 | AC7: 無 | AE7: 2 | AF7: Z3932 | AG7: -site:"Z3932" | AH7: 倉庫在庫データ.csv | AI7: A4000 | AJ7: A3 | AK7: 5000 | AL7: 26 | AM7: AA | AN7: Z | AO7: 41 | AP7: 63 | AQ7: 22 | AR7: W | AS7: V | AT7: 41 | AU7: 63 | AV7: 有 | AW7: 部署別テーブル参照 | AX7: 発注点リセット_部署別設定シート | AY7: 有 | BA7: 1 | BB7: 27 | BC7: 在庫切れ | BD7: 在庫額 | BE7: 欠品（色） | BF7: 在庫額（色） | BG7: 在庫帳
A8: 有 | C8: Z1915 | D8: 船舶(機械部) | E8: -site:"Z1915" | F8: 船舶在庫データ.csv | G8: 船舶在庫帳.xlsx | H8: \\192.168.0.35\disk\企画室\倉庫\前日データ\船舶在庫帳.xlsx | I8: \\192.168.0.35\disk\企画室\倉庫 | J8: 25 | K8: Z | L8: Y | M8: 24 | N8: 52 | O8: 23 | P8: X | Q8: W | R8: 21 | S8: 49 | T8: D | U8: 3000 | V8: 25 | W8: 有 | X8: 有 | Y8: 有 | Z8: 有(PowerShell方式) | AA8: 有 | AB8: 無 | AC8: 有 | AD8: TIMS_C05_InvntInq.exe | AE8: 1 | AI8: A3 | AV8: 有 | AW8: 部署別テーブル参照 | AX8: 発注点リセット_部署別設定シート | AY8: 有 | BA8: 1 | BB8: 25 | BC8: 欠品 | BD8: 在庫額 | BG8: 在庫帳
A9: 有 | C9: Z1903 | D9: 仙台 | E9: -site:"Z1903" | F9: 仙台在庫データ.csv | G9: 仙台在庫帳.xlsx | H9: \\192.168.0.35\disk\企画室\倉庫\前日データ\仙台在庫帳.xlsx | I9: \\192.168.0.35\disk\企画室\倉庫 | J9: 23 | K9: X | L9: W | M9: 37 | N9: 58 | O9: 23 | P9: X | Q9: W | R9: 37 | S9: 60 | T9: D | U9: 3000 | V9: 18 | W9: 無 | X9: 無 | Y9: 無 | Z9: 有(Excel置換方式) | AA9: 有 | AB9: 無 | AC9: 無 | AE9: 1 | AI9: A3 | AV9: 有 | AW9: 部署別テーブル参照 | AX9: 発注点リセット_部署別設定シート | AY9: 有 | BA9: 1 | BB9: 18 | BC9: 欠品 | BD9: 在庫額 | BG9: 在庫帳
A10: 有 | C10: Z1907 | D10: 福岡 | E10: -site:"Z1907" | F10: 福岡在庫データ.csv | G10: 福岡在庫帳.xlsx | H10: \\192.168.0.35\disk\企画室\倉庫\前日データ\福岡在庫帳.xlsx | I10: \\192.168.0.35\disk\企画室\倉庫 | J10: 23 | K10: X | L10: W | M10: 29 | N10: 50 | O10: 20 | P10: U | Q10: T | R10: 32 | S10: 54 | T10: D | U10: 4000 | V10: 19 | W10: 無 | X10: 無 | Y10: 無 | Z10: 有(Excel置換方式) | AA10: 有 | AB10: 無 | AC10: 無 | AE10: 1 | AI10: A3 | AV10: 有 | AW10: 部署別テーブル参照 | AX10: 発注点リセット_部署別設定シート | AY10: 有 | BA10: 1 | BB10: 19 | BC10: 欠品 | BD10: 在庫額 | BG10: 在庫帳
A11: 有 | C11: Z1905 | D11: 東京 | E11: -site:"Z1905" | F11: 東京在庫データ.csv | G11: 東京在庫帳.xlsx | H11: \\192.168.0.35\disk\企画室\倉庫\前日データ\東京在庫帳.xlsx | I11: \\192.168.0.35\disk\企画室\倉庫 | J11: 25 | K11: Z | L11: Y | M11: 27 | N11: 48 | O11: 23 | P11: X | Q11: W | R11: 29 | S11: 52 | T11: D | U11: 2000 | V11: 16 | W11: 無 | X11: 無 | Y11: 無 | Z11: 有(Excel置換方式) | AA11: 有 | AB11: 無 | AC11: 無 | AE11: 1 | AI11: A3 | AV11: 有 | AW11: 部署別テーブル参照 | AX11: 発注点リセット_部署別設定シート | AY11: 有(2026/7/3。ローカル保存のみのため実際の稼働有無は別途要確認だが、統合対象としては有効) | BA11: 1 | BB11: 19 | BC11: 欠品 | BD11: 在庫額 | BG11: 在庫帳
A12: 有 | C12: Z3934 | D12: 成果連絡表(色物) | E12: -site:"Z3934" | F12: 外注在庫データ.csv | G12: 成果連絡表（色物）.xlsx | H12: \\192.168.0.35\disk\企画室\倉庫\前日データ\成果連絡表（色物）.xlsx | I12: \\192.168.0.35\disk\企画室\倉庫 | T12: D | U12: 4000 | V12: 18 | W12: 無 | X12: 無 | Y12: 無※資料上確認できず | Z12: 有(PowerShell方式) | AA12: 有 | AB12: 無※要確認 | AC12: 有 | AD12: TIMS_ClientPC.exe / TIMS_C05_InvntInq.exe | AE12: 2 | AF12: Z3932 | AG12: -site:"Z3932" | AH12: 倉庫在庫データ.csv | AI12: A4034 | AJ12: A3 | AK12: 5000 | AL12: 28 | AM12: AC | AN12: AB | AO12: 41 | AP12: 61 | AQ12: 30 | AR12: AE | AS12: AD | AT12: 41 | AU12: 61 | AY12: 有(2026/7/3時点、共有フォルダで本日更新を確認済み) | BA12: 1 | BB12: 18 | BE12: 欠品 | BF12: 発注点割れ | BG12: 在庫帳

Sheet 管理対象外シート
A1: 拠点名 | B1: シート番号 | C1: 理由
A2: 外注鉄 | B2: 18 | C2: 管理対象外

Sheet 列加工定義
A1: 拠点名 | B1: 区分 | C1: 系統 | D1: シート名 | E1: 列削除_開始位置 | F1: 列挿入位置 | G1: ステップ番号 | H1: コピー範囲 | I1: 貼付先セル | J1: 貼付形式 | K1: 備考 | L1: 列削除列挿入_要否
A2: =拠点別設定値!D4 -> 札幌 | B2: 欠品 | C2: 標準 | D2: =拠点別設定値!BC4 -> 欠品 | E2: 2 | F2: =拠点別設定値!J4 -> 23 | G2: 1 | H2: =拠点別設定値!K4&拠点別設定値!M4&":"&拠点別設定値!K4&拠点別設定値!N4 -> X27:X48 | I2: =拠点別設定値!L4&拠点別設定値!M4 -> W27 | J2: 値 | L2: =IF(G2=1,"有","無") -> 有
A3: =拠点別設定値!D4 -> 札幌 | B3: 欠品 | C3: 標準 | D3: =拠点別設定値!BC4 -> 欠品 | E3: 2 | F3: =拠点別設定値!J4 -> 23 | G3: 2 | H3: =拠点別設定値!K4&(拠点別設定値!M4+1)&":"&拠点別設定値!K4&(拠点別設定値!M4+2) -> X28:X29 | I3: =拠点別設定値!L4&(拠点別設定値!M4+1) -> W28 | J3: すべて | K3: 末尾2行(書式ずれ対策)。2026/7/6荘田室長回答により貼付形式は「値」に統一／2026/8/5 実データ検証済み：V1.0個別シナリオ(外注鉄・仙台)と同じ「すべて」に統一。全9拠点の答えファイルで位置(処理開始行+1=目標値行)を実機照合済み | L3: =IF(G3=1,"有","無") -> 無
A4: =拠点別設定値!D4 -> 札幌 | B4: 在庫額 | C4: 標準 | D4: =拠点別設定値!BD4 -> 在庫額 | E4: 2 | F4: =拠点別設定値!O4 -> 21 | G4: 1 | H4: =拠点別設定値!P4&拠点別設定値!R4&":"&拠点別設定値!P4&拠点別設定値!S4 -> V29:V52 | I4: =拠点別設定値!Q4&拠点別設定値!R4 -> U29 | J4: 値 | L4: =IF(G4=1,"有","無") -> 有
A5: =拠点別設定値!D4 -> 札幌 | B5: 在庫額 | C5: 標準 | D5: =拠点別設定値!BD4 -> 在庫額 | E5: 2 | F5: =拠点別設定値!O4 -> 21 | G5: 2 | H5: =拠点別設定値!P4&(拠点別設定値!R4+1)&":"&拠点別設定値!P4&(拠点別設定値!R4+2) -> V30:V31 | I5: =拠点別設定値!Q4&(拠点別設定値!R4+1) -> U30 | J5: すべて | K5: 末尾2行(書式ずれ対策)。2026/7/6荘田室長回答により貼付形式は「値」に統一／2026/8/5 実データ検証済み：V1.0個別シナリオ(外注鉄・仙台)と同じ「すべて」に統一。全9拠点の答えファイルで位置(処理開始行+1=目標値行)を実機照合済み | L5: =IF(G5=1,"有","無") -> 無
A6: =拠点別設定値!D5 -> 倉庫(本社) | B6: 欠品 | C6: 標準 | D6: =拠点別設定値!BC5 -> 欠品 | E6: 2 | F6: =拠点別設定値!J5 -> 24 | G6: 1 | H6: =拠点別設定値!K5&拠点別設定値!M5&":"&拠点別設定値!K5&拠点別設定値!N5 -> Y37:Y58 | I6: =拠点別設定値!L5&拠点別設定値!M5 -> X37 | J6: 値 | L6: =IF(G6=1,"有","無") -> 有
A7: =拠点別設定値!D5 -> 倉庫(本社) | B7: 欠品 | C7: 標準 | D7: =拠点別設定値!BC5 -> 欠品 | E7: 2 | F7: =拠点別設定値!J5 -> 24 | G7: 2 | H7: =拠点別設定値!K5&(拠点別設定値!M5+1)&":"&拠点別設定値!K5&(拠点別設定値!M5+2) -> Y38:Y39 | I7: =拠点別設定値!L5&(拠点別設定値!M5+1) -> X38 | J7: すべて | K7: 末尾2行(書式ずれ対策)。2026/7/6荘田室長回答により貼付形式は「値」に統一／2026/8/5 実データ検証済み：V1.0個別シナリオ(外注鉄・仙台)と同じ「すべて」に統一。全9拠点の答えファイルで位置(処理開始行+1=目標値行)を実機照合済み | L7: =IF(G7=1,"有","無") -> 無
A8: =拠点別設定値!D5 -> 倉庫(本社) | B8: 在庫額 | C8: 標準 | D8: =拠点別設定値!BD5 -> 在庫額 | E8: 2 | F8: =拠点別設定値!O5 -> 20 | G8: 1 | H8: =拠点別設定値!P5&拠点別設定値!R5&":"&拠点別設定値!P5&拠点別設定値!S5 -> U37:U60 | I8: =拠点別設定値!Q5&拠点別設定値!R5 -> T37 | J8: 値 | L8: =IF(G8=1,"有","無") -> 有
A9: =拠点別設定値!D5 -> 倉庫(本社) | B9: 在庫額 | C9: 標準 | D9: =拠点別設定値!BD5 -> 在庫額 | E9: 2 | F9: =拠点別設定値!O5 -> 20 | G9: 2 | H9: =拠点別設定値!P5&(拠点別設定値!R5+1)&":"&拠点別設定値!P5&(拠点別設定値!R5+2) -> U38:U39 | I9: =拠点別設定値!Q5&(拠点別設定値!R5+1) -> T38 | J9: すべて | K9: 末尾2行(書式ずれ対策)。2026/7/6荘田室長回答により貼付形式は「値」に統一／2026/8/5 実データ検証済み：V1.0個別シナリオ(外注鉄・仙台)と同じ「すべて」に統一。全9拠点の答えファイルで位置(処理開始行+1=目標値行)を実機照合済み | L9: =IF(G9=1,"有","無") -> 無
A10: =拠点別設定値!D6 -> 製造(大型) | B10: 欠品 | C10: 標準 | D10: =拠点別設定値!BC6 -> 欠品 | E10: 2 | F10: =拠点別設定値!J6 -> 29 | G10: 1 | H10: =拠点別設定値!K6&拠点別設定値!M6&":"&拠点別設定値!K6&拠点別設定値!N6 -> AD37:AD47 | I10: =拠点別設定値!L6&拠点別設定値!M6 -> AC37 | J10: 値 | L10: =IF(G10=1,"有","無") -> 有
A11: =拠点別設定値!D6 -> 製造(大型) | B11: 欠品 | C11: 標準 | D11: =拠点別設定値!BC6 -> 欠品 | E11: 2 | F11: =拠点別設定値!J6 -> 29 | G11: 2 | H11: =拠点別設定値!K6&(拠点別設定値!M6+1)&":"&拠点別設定値!K6&(拠点別設定値!M6+2) -> AD38:AD39 | I11: =拠点別設定値!L6&(拠点別設定値!M6+1) -> AC38 | J11: すべて | K11: 末尾2行(書式ずれ対策)。2026/7/6荘田室長回答により貼付形式は「値」に統一／2026/8/5 実データ検証済み：V1.0個別シナリオ(外注鉄・仙台)と同じ「すべて」に統一。全9拠点の答えファイルで位置(処理開始行+1=目標値行)を実機照合済み | L11: =IF(G11=1,"有","無") -> 無
A12: =拠点別設定値!D6 -> 製造(大型) | B12: 在庫額 | C12: 標準 | D12: =拠点別設定値!BD6 -> 在庫額 | E12: 2 | F12: =拠点別設定値!O6 -> 26 | G12: 1 | H12: =拠点別設定値!P6&拠点別設定値!R6&":"&拠点別設定値!P6&拠点別設定値!S6 -> AA37:AA48 | I12: =拠点別設定値!Q6&拠点別設定値!R6 -> Z37 | J12: 値 | L12: =IF(G12=1,"有","無") -> 有
A13: =拠点別設定値!D6 -> 製造(大型) | B13: 在庫額 | C13: 標準 | D13: =拠点別設定値!BD6 -> 在庫額 | E13: 2 | F13: =拠点別設定値!O6 -> 26 | G13: 2 | H13: =拠点別設定値!P6&(拠点別設定値!R6+1)&":"&拠点別設定値!P6&(拠点別設定値!R6+2) -> AA38:AA39 | I13: =拠点別設定値!Q6&(拠点別設定値!R6+1) -> Z38 | J13: すべて | K13: 末尾2行(書式ずれ対策)。2026/7/6荘田室長回答により貼付形式は「値」に統一／2026/8/5 実データ検証済み：V1.0個別シナリオ(外注鉄・仙台)と同じ「すべて」に統一。全9拠点の答えファイルで位置(処理開始行+1=目標値行)を実機照合済み | L13: =IF(G13=1,"有","無") -> 無
A14: =拠点別設定値!D7 -> 外注鉄 | B14: 欠品 | C14: 標準 | D14: =拠点別設定値!BC7 -> 在庫切れ | E14: 2 | F14: =拠点別設定値!J7 -> 22 | G14: 1 | H14: =拠点別設定値!K7&拠点別設定値!M7&":"&拠点別設定値!K7&拠点別設定値!N7 -> W27:W36 | I14: =拠点別設定値!L7&拠点別設定値!M7 -> V27 | J14: 値 | L14: =IF(G14=1,"有","無") -> 有
A15: =拠点別設定値!D7 -> 外注鉄 | B15: 欠品 | C15: 標準 | D15: =拠点別設定値!BC7 -> 在庫切れ | E15: 2 | F15: =拠点別設定値!J7 -> 22 | G15: 2 | H15: =拠点別設定値!K7&(拠点別設定値!M7+1)&":"&拠点別設定値!K7&(拠点別設定値!M7+2) -> W28:W29 | I15: =拠点別設定値!L7&(拠点別設定値!M7+1) -> V28 | J15: すべて | K15: 末尾2行(書式ずれ対策)。2026/7/6荘田室長回答により貼付形式は「値」に統一／2026/8/5 実データ検証済み：V1.0個別シナリオ(外注鉄・仙台)と同じ「すべて」に統一。全9拠点の答えファイルで位置(処理開始行+1=目標値行)を実機照合済み | L15: =IF(G15=1,"有","無") -> 無
A16: =拠点別設定値!D7 -> 外注鉄 | B16: 在庫額 | C16: 標準 | D16: =拠点別設定値!BD7 -> 在庫額 | E16: 2 | F16: =拠点別設定値!O7 -> 21 | G16: 1 | H16: =拠点別設定値!P7&拠点別設定値!R7&":"&拠点別設定値!P7&拠点別設定値!S7 -> V28:V39 | I16: =拠点別設定値!Q7&拠点別設定値!R7 -> U28 | J16: 値 | L16: =IF(G16=1,"有","無") -> 有
A17: =拠点別設定値!D7 -> 外注鉄 | B17: 在庫額 | C17: 標準 | D17: =拠点別設定値!BD7 -> 在庫額 | E17: 2 | F17: =拠点別設定値!O7 -> 21 | G17: 2 | H17: =拠点別設定値!P7&(拠点別設定値!R7+1)&":"&拠点別設定値!P7&(拠点別設定値!R7+2) -> V29:V30 | I17: =拠点別設定値!Q7&(拠点別設定値!R7+1) -> U29 | J17: すべて | K17: 末尾2行(書式ずれ対策)。2026/7/6荘田室長回答により貼付形式は「値」に統一／2026/8/5 実データ検証済み：V1.0個別シナリオ(外注鉄・仙台)と同じ「すべて」に統一。全9拠点の答えファイルで位置(処理開始行+1=目標値行)を実機照合済み | L17: =IF(G17=1,"有","無") -> 無
A18: =拠点別設定値!D7 -> 外注鉄 | B18: 欠品 | C18: 色物 | D18: =拠点別設定値!BE7 -> 欠品（色） | E18: 2 | F18: =拠点別設定値!AL7 -> 26 | G18: 1 | H18: =拠点別設定値!AM7&拠点別設定値!AO7&":"&拠点別設定値!AM7&拠点別設定値!AP7 -> AA41:AA63 | I18: =拠点別設定値!AN7&拠点別設定値!AO7 -> Z41 | J18: 値 | L18: =IF(G18=1,"有","無") -> 有
A19: =拠点別設定値!D7 -> 外注鉄 | B19: 欠品 | C19: 色物 | D19: =拠点別設定値!BE7 -> 欠品（色） | E19: 2 | F19: =拠点別設定値!AL7 -> 26 | G19: 2 | H19: =拠点別設定値!AM7&(拠点別設定値!AO7+1)&":"&拠点別設定値!AM7&(拠点別設定値!AO7+2) -> AA42:AA43 | I19: =拠点別設定値!AN7&(拠点別設定値!AO7+1) -> Z42 | J19: すべて | K19: 末尾2行(書式ずれ対策)。2026/7/6荘田室長回答により貼付形式は「値」に統一／2026/8/5 実データ検証済み：V1.0個別シナリオ(外注鉄・仙台)と同じ「すべて」に統一。全9拠点の答えファイルで位置(処理開始行+1=目標値行)を実機照合済み | L19: =IF(G19=1,"有","無") -> 無
A20: =拠点別設定値!D7 -> 外注鉄 | B20: 在庫額 | C20: 色物 | D20: =拠点別設定値!BF7 -> 在庫額（色） | E20: 2 | F20: =拠点別設定値!AQ7 -> 22 | G20: 1 | H20: =拠点別設定値!AR7&拠点別設定値!AT7&":"&拠点別設定値!AR7&拠点別設定値!AU7 -> W41:W63 | I20: =拠点別設定値!AS7&拠点別設定値!AT7 -> V41 | J20: 値 | L20: =IF(G20=1,"有","無") -> 有
A21: =拠点別設定値!D7 -> 外注鉄 | B21: 在庫額 | C21: 色物 | D21: =拠点別設定値!BF7 -> 在庫額（色） | E21: 2 | F21: =拠点別設定値!AQ7 -> 22 | G21: 2 | H21: =拠点別設定値!AR7&(拠点別設定値!AT7+1)&":"&拠点別設定値!AR7&(拠点別設定値!AT7+2) -> W42:W43 | I21: =拠点別設定値!AS7&(拠点別設定値!AT7+1) -> V42 | J21: すべて | K21: 末尾2行(書式ずれ対策)。2026/7/6荘田室長回答により貼付形式は「値」に統一／2026/8/5 実データ検証済み：V1.0個別シナリオ(外注鉄・仙台)と同じ「すべて」に統一。全9拠点の答えファイルで位置(処理開始行+1=目標値行)を実機照合済み | L21: =IF(G21=1,"有","無") -> 無
A22: =拠点別設定値!D8 -> 船舶(機械部) | B22: 欠品 | C22: 標準 | D22: =拠点別設定値!BC8 -> 欠品 | E22: 2 | F22: =拠点別設定値!J8 -> 25 | G22: 1 | H22: =拠点別設定値!K8&拠点別設定値!M8&":"&拠点別設定値!K8&拠点別設定値!N8 -> Z24:Z52 | I22: =拠点別設定値!L8&拠点別設定値!M8 -> Y24 | J22: 値 | L22: =IF(G22=1,"有","無") -> 有
A23: =拠点別設定値!D8 -> 船舶(機械部) | B23: 欠品 | C23: 標準 | D23: =拠点別設定値!BC8 -> 欠品 | E23: 2 | F23: =拠点別設定値!J8 -> 25 | G23: 2 | H23: =拠点別設定値!K8&(拠点別設定値!M8+1)&":"&拠点別設定値!K8&(拠点別設定値!M8+2) -> Z25:Z26 | I23: =拠点別設定値!L8&(拠点別設定値!M8+1) -> Y25 | J23: すべて | K23: 末尾2行(書式ずれ対策)。2026/7/6荘田室長回答により貼付形式は「値」に統一／2026/8/5 実データ検証済み：V1.0個別シナリオ(外注鉄・仙台)と同じ「すべて」に統一。全9拠点の答えファイルで位置(処理開始行+1=目標値行)を実機照合済み | L23: =IF(G23=1,"有","無") -> 無
A24: =拠点別設定値!D8 -> 船舶(機械部) | B24: 在庫額 | C24: 標準 | D24: =拠点別設定値!BD8 -> 在庫額 | E24: 2 | F24: =拠点別設定値!O8 -> 23 | G24: 1 | H24: =拠点別設定値!P8&拠点別設定値!R8&":"&拠点別設定値!P8&拠点別設定値!S8 -> X21:X49 | I24: =拠点別設定値!Q8&拠点別設定値!R8 -> W21 | J24: 値 | L24: =IF(G24=1,"有","無") -> 有
A25: =拠点別設定値!D8 -> 船舶(機械部) | B25: 在庫額 | C25: 標準 | D25: =拠点別設定値!BD8 -> 在庫額 | E25: 2 | F25: =拠点別設定値!O8 -> 23 | G25: 2 | H25: =拠点別設定値!P8&(拠点別設定値!R8+1)&":"&拠点別設定値!P8&(拠点別設定値!R8+2) -> X22:X23 | I25: =拠点別設定値!Q8&(拠点別設定値!R8+1) -> W22 | J25: すべて | K25: 末尾2行(書式ずれ対策)。2026/7/6荘田室長回答により貼付形式は「値」に統一／2026/8/5 実データ検証済み：V1.0個別シナリオ(外注鉄・仙台)と同じ「すべて」に統一。全9拠点の答えファイルで位置(処理開始行+1=目標値行)を実機照合済み | L25: =IF(G25=1,"有","無") -> 無
A26: =拠点別設定値!D9 -> 仙台 | B26: 欠品 | C26: 標準 | D26: =拠点別設定値!BC9 -> 欠品 | E26: 2 | F26: =拠点別設定値!J9 -> 23 | G26: 1 | H26: =拠点別設定値!K9&拠点別設定値!M9&":"&拠点別設定値!K9&拠点別設定値!N9 -> X37:X58 | I26: =拠点別設定値!L9&拠点別設定値!M9 -> W37 | J26: 値 | L26: =IF(G26=1,"有","無") -> 有
A27: =拠点別設定値!D9 -> 仙台 | B27: 欠品 | C27: 標準 | D27: =拠点別設定値!BC9 -> 欠品 | E27: 2 | F27: =拠点別設定値!J9 -> 23 | G27: 2 | H27: =拠点別設定値!K9&(拠点別設定値!M9+1)&":"&拠点別設定値!K9&(拠点別設定値!M9+2) -> X38:X39 | I27: =拠点別設定値!L9&(拠点別設定値!M9+1) -> W38 | J27: すべて | K27: 末尾2行(書式ずれ対策)。2026/7/6荘田室長回答により貼付形式は「値」に統一／2026/8/5 実データ検証済み：V1.0個別シナリオ(外注鉄・仙台)と同じ「すべて」に統一。全9拠点の答えファイルで位置(処理開始行+1=目標値行)を実機照合済み | L27: =IF(G27=1,"有","無") -> 無
A28: =拠点別設定値!D9 -> 仙台 | B28: 在庫額 | C28: 標準 | D28: =拠点別設定値!BD9 -> 在庫額 | E28: 2 | F28: =拠点別設定値!O9 -> 23 | G28: 1 | H28: =拠点別設定値!P9&拠点別設定値!R9&":"&拠点別設定値!P9&拠点別設定値!S9 -> X37:X60 | I28: =拠点別設定値!Q9&拠点別設定値!R9 -> W37 | J28: 値 | L28: =IF(G28=1,"有","無") -> 有
A29: =拠点別設定値!D9 -> 仙台 | B29: 在庫額 | C29: 標準 | D29: =拠点別設定値!BD9 -> 在庫額 | E29: 2 | F29: =拠点別設定値!O9 -> 23 | G29: 2 | H29: =拠点別設定値!P9&(拠点別設定値!R9+1)&":"&拠点別設定値!P9&(拠点別設定値!R9+2) -> X38:X39 | I29: =拠点別設定値!Q9&(拠点別設定値!R9+1) -> W38 | J29: すべて | K29: 末尾2行(書式ずれ対策)。2026/7/6荘田室長回答により貼付形式は「値」に統一／2026/8/5 実データ検証済み：V1.0個別シナリオ(外注鉄・仙台)と同じ「すべて」に統一。全9拠点の答えファイルで位置(処理開始行+1=目標値行)を実機照合済み | L29: =IF(G29=1,"有","無") -> 無
A30: =拠点別設定値!D10 -> 福岡 | B30: 欠品 | C30: 標準 | D30: =拠点別設定値!BC10 -> 欠品 | E30: 2 | F30: =拠点別設定値!J10 -> 23 | G30: 1 | H30: =拠点別設定値!K10&拠点別設定値!M10&":"&拠点別設定値!K10&拠点別設定値!N10 -> X29:X50 | I30: =拠点別設定値!L10&拠点別設定値!M10 -> W29 | J30: 値 | L30: =IF(G30=1,"有","無") -> 有
A31: =拠点別設定値!D10 -> 福岡 | B31: 欠品 | C31: 標準 | D31: =拠点別設定値!BC10 -> 欠品 | E31: 2 | F31: =拠点別設定値!J10 -> 23 | G31: 2 | H31: =拠点別設定値!K10&(拠点別設定値!M10+1)&":"&拠点別設定値!K10&(拠点別設定値!M10+2) -> X30:X31 | I31: =拠点別設定値!L10&(拠点別設定値!M10+1) -> W30 | J31: すべて | K31: 末尾2行(書式ずれ対策)。2026/7/6荘田室長回答により貼付形式は「値」に統一／2026/8/5 実データ検証済み：V1.0個別シナリオ(外注鉄・仙台)と同じ「すべて」に統一。全9拠点の答えファイルで位置(処理開始行+1=目標値行)を実機照合済み | L31: =IF(G31=1,"有","無") -> 無
A32: =拠点別設定値!D10 -> 福岡 | B32: 在庫額 | C32: 標準 | D32: =拠点別設定値!BD10 -> 在庫額 | E32: 2 | F32: =拠点別設定値!O10 -> 20 | G32: 1 | H32: =拠点別設定値!P10&拠点別設定値!R10&":"&拠点別設定値!P10&拠点別設定値!S10 -> U32:U54 | I32: =拠点別設定値!Q10&拠点別設定値!R10 -> T32 | J32: 値 | L32: =IF(G32=1,"有","無") -> 有
A33: =拠点別設定値!D10 -> 福岡 | B33: 在庫額 | C33: 標準 | D33: =拠点別設定値!BD10 -> 在庫額 | E33: 2 | F33: =拠点別設定値!O10 -> 20 | G33: 2 | H33: =拠点別設定値!P10&(拠点別設定値!R10+1)&":"&拠点別設定値!P10&(拠点別設定値!R10+2) -> U33:U34 | I33: =拠点別設定値!Q10&(拠点別設定値!R10+1) -> T33 | J33: すべて | K33: 末尾2行(書式ずれ対策)。2026/7/6荘田室長回答により貼付形式は「値」に統一／2026/8/5 実データ検証済み：V1.0個別シナリオ(外注鉄・仙台)と同じ「すべて」に統一。全9拠点の答えファイルで位置(処理開始行+1=目標値行)を実機照合済み | L33: =IF(G33=1,"有","無") -> 無
A34: =拠点別設定値!D11 -> 東京 | B34: 欠品 | C34: 標準 | D34: =拠点別設定値!BC11 -> 欠品 | E34: 2 | F34: =拠点別設定値!J11 -> 25 | G34: 1 | H34: =拠点別設定値!K11&拠点別設定値!M11&":"&拠点別設定値!K11&拠点別設定値!N11 -> Z27:Z48 | I34: =拠点別設定値!L11&拠点別設定値!M11 -> Y27 | J34: 値 | L34: =IF(G34=1,"有","無") -> 有
A35: =拠点別設定値!D11 -> 東京 | B35: 欠品 | C35: 標準 | D35: =拠点別設定値!BC11 -> 欠品 | E35: 2 | F35: =拠点別設定値!J11 -> 25 | G35: 2 | H35: =拠点別設定値!K11&(拠点別設定値!M11+1)&":"&拠点別設定値!K11&(拠点別設定値!M11+2) -> Z28:Z29 | I35: =拠点別設定値!L11&(拠点別設定値!M11+1) -> Y28 | J35: すべて | K35: 末尾2行(書式ずれ対策)。2026/7/6荘田室長回答により貼付形式は「値」に統一／2026/8/5 実データ検証済み：V1.0個別シナリオ(外注鉄・仙台)と同じ「すべて」に統一。全9拠点の答えファイルで位置(処理開始行+1=目標値行)を実機照合済み | L35: =IF(G35=1,"有","無") -> 無
A36: =拠点別設定値!D11 -> 東京 | B36: 在庫額 | C36: 標準 | D36: =拠点別設定値!BD11 -> 在庫額 | E36: 2 | F36: =拠点別設定値!O11 -> 23 | G36: 1 | H36: =拠点別設定値!P11&拠点別設定値!R11&":"&拠点別設定値!P11&拠点別設定値!S11 -> X29:X52 | I36: =拠点別設定値!Q11&拠点別設定値!R11 -> W29 | J36: 値 | L36: =IF(G36=1,"有","無") -> 有
A37: =拠点別設定値!D11 -> 東京 | B37: 在庫額 | C37: 標準 | D37: =拠点別設定値!BD11 -> 在庫額 | E37: 2 | F37: =拠点別設定値!O11 -> 23 | G37: 2 | H37: =拠点別設定値!P11&(拠点別設定値!R11+1)&":"&拠点別設定値!P11&(拠点別設定値!R11+2) -> X30:X31 | I37: =拠点別設定値!Q11&(拠点別設定値!R11+1) -> W30 | J37: すべて | K37: 末尾2行(書式ずれ対策)。2026/7/6荘田室長回答により貼付形式は「値」に統一／2026/8/5 実データ検証済み：V1.0個別シナリオ(外注鉄・仙台)と同じ「すべて」に統一。全9拠点の答えファイルで位置(処理開始行+1=目標値行)を実機照合済み | L37: =IF(G37=1,"有","無") -> 無
A38: =拠点別設定値!D12 -> 成果連絡表(色物) | B38: 欠品 | C38: 色物 | D38: =拠点別設定値!BE12 -> 欠品 | E38: 2 | F38: =拠点別設定値!AL12 -> 28 | G38: 1 | H38: =拠点別設定値!AM12&拠点別設定値!AO12&":"&拠点別設定値!AM12&拠点別設定値!AP12 -> AC41:AC61 | I38: =拠点別設定値!AN12&拠点別設定値!AO12 -> AB41 | J38: 値 | L38: =IF(G38=1,"有","無") -> 有
A39: =拠点別設定値!D12 -> 成果連絡表(色物) | B39: 欠品 | C39: 色物 | D39: =拠点別設定値!BE12 -> 欠品 | E39: 2 | F39: =拠点別設定値!AL12 -> 28 | G39: 2 | H39: =拠点別設定値!AM12&(拠点別設定値!AO12+1)&":"&拠点別設定値!AM12&(拠点別設定値!AO12+2) -> AC42:AC43 | I39: =拠点別設定値!AN12&(拠点別設定値!AO12+1) -> AB42 | J39: すべて | K39: 末尾2行(書式ずれ対策)。2026/7/6荘田室長回答により貼付形式は「値」に統一／2026/8/5 実データ検証済み：V1.0個別シナリオ(外注鉄・仙台)と同じ「すべて」に統一。全9拠点の答えファイルで位置(処理開始行+1=目標値行)を実機照合済み | L39: =IF(G39=1,"有","無") -> 無
A40: =拠点別設定値!D12 -> 成果連絡表(色物) | B40: 在庫額 | C40: 色物 | D40: =拠点別設定値!BF12 -> 発注点割れ | E40: 2 | F40: =拠点別設定値!AQ12 -> 30 | G40: 1 | H40: =拠点別設定値!AR12&拠点別設定値!AT12&":"&拠点別設定値!AR12&拠点別設定値!AU12 -> AE41:AE61 | I40: =拠点別設定値!AS12&拠点別設定値!AT12 -> AD41 | J40: 値 | L40: =IF(G40=1,"有","無") -> 有
...

Sheet 変数定義一覧
A1: 区分 | B1: 変数名 | C1: 型 | D1: 説明 | E1: 備考
A2: 基本情報 | B2: 拠点コード | C2: 文字列 | D2: TIMS起動時の-siteパラメータに使う識別コード
B3: 拠点名 | C3: 文字列 | D3: 表示・ログ出力用の拠点名
B4: TIMS起動引数 | C4: 文字列 | D4: TIMS_ClientPC.exe起動時の引数（-site:"コード"） | E4: 拠点コードから組立可
B5: CSVファイル名 | C5: 文字列 | D5: TIMSからエクスポートするCSVのファイル名
B6: 在庫帳ブック名 | C6: 文字列 | D6: 処理対象の在庫帳/日報Excelファイル名
B7: 保存先(ネットワーク)フルパス | C7: 文字列 | D7: 処理後にファイルを保存するネットワーク共有先
A8: 欠品シート構造 | B8: 欠品_列挿入位置 | C8: 整数 | D8: 欠品シートで新規列を挿入する位置 | E8: テンプレート由来の差異
B9: 欠品_コピペ元列 | C9: 列記号 | D9: コピー元の列（挿入前の最終列相当）
B10: 欠品_コピペ先列 | C10: 列記号 | D10: 貼り付け先の列（挿入で1列前にずれた列）
B11: 欠品_処理開始行 | C11: 整数 | D11: 欠品データの処理開始行 | E11: 将来的に動的取得へ置換候補
B12: 欠品_処理終了行 | C12: 整数 | D12: 欠品データの処理終了行 | E12: 将来的に動的取得へ置換候補
A13: 在庫額シート構造 | B13: 在庫額_列挿入位置 | C13: 整数 | D13: 在庫額シートで新規列を挿入する位置 | E13: テンプレート由来の差異
B14: 在庫額_コピペ元列 | C14: 列記号 | D14: コピー元の列
B15: 在庫額_コピペ先列 | C15: 列記号 | D15: 貼り付け先の列
B16: 在庫額_処理開始行 | C16: 整数 | D16: 在庫額データの処理開始行 | E16: 将来的に動的取得へ置換候補
B17: 在庫額_処理終了行 | C17: 整数 | D17: 在庫額データの処理終了行 | E17: 将来的に動的取得へ置換候補
A18: CSV/ループ | B18: CSV範囲_終端列 | C18: 列記号 | D18: CSVコピペ範囲の終端列
B19: CSV範囲_終端行 | C19: 整数 | D19: CSVコピペ範囲の終端行（現状は固定値） | E19: 将来的に「最初の空行」で動的化候補
B20: シートループ回数 | C20: 整数 | D20: 拠点別データシート(1,2,3...)を処理する回数 | E20: 将来的にシート数取得で動的化候補 2026/7/6：終了番号との不一致時の挙動仕様は「処理対象シート_終了番号」の備考を参照。
A21: 処理フラグ | B21: 休日判定_実行 | C21: 有/無 | D21: カレンダー参照による休日スキップ処理を行うか | E21: 倉庫・製造・船舶は有、札幌は無
B22: ネット事前取得_実行 | C22: 有/無 | D22: 処理前にネットワークから最新ブックをローカルへ取得するか | E22: 倉庫・製造・船舶は有、札幌は無
B23: OLDバックアップ_実行 | C23: 有/無 | D23: 処理前の旧ファイルをOLDフォルダへ退避するか | E23: 倉庫・船舶は有、製造は要確認、札幌は無
B24: CSV空白除去_実行 | C24: 有/無 | D24: TIMS出力CSVの余分な半角スペースをPowerShellで除去するか | E24: 2026/7/3 天野判断：TIMS出力CSVは全拠点で半角スペース混入が常態であり、後工程(COUNTIF等の一致判定)に支障が出るため、方式(PowerShell/Excel置換)は問わず全拠点で有効化を必須とする。札幌は現行シナリオに同処理が無く、統合版での新規実装対象。
B25: 発注点補正_実行 | C25: 有/無 | D25: COUNTIFによる発注点(E列)未設定商品への自動補完を行うか | E25: 2026/7/3 荘田室長口頭確認により全拠点共通実装に決定（発注点0かつ在庫>0の場合、在庫数を発注点に書き換え）
B26: O列転記_実行 | C26: 有/無 | D26: O列(発注点-在庫数)の値をE列へ転記する処理を行うか | E26: 製造のみ有（倉庫・札幌・船舶は無）
A27: プロセス終了 | B27: 追加終了プロセス_実行 | C27: 有/無 | D27: TIMS_ClientPC.exeに加えて追加のプロセスも終了するか | E27: 倉庫・製造・船舶は有、札幌は無
B28: 追加終了プロセス名 | C28: 文字列 | D28: 追加で終了するプロセスの実行ファイル名 | E28: TIMS_C05_InvntInq.exe 等
A29: 複数CSVデータセット | B29: CSVデータセット数 | C29: 整数 | D29: 1回のシナリオでTIMSから取得して在庫帳へ貼り付けるCSVの本数 | E29: 表示・確認用の参考値。シナリオ本体の分岐条件は「副拠点コード」の有無を用いる。
B30: 副拠点コード | C30: 文字列 | D30: 2本目のCSVを取得するTIMS拠点コード | E30: 2026/7/3決定：統合シナリオはこの値が空欄かどうかで2本目のCSV取得要否を判定する(空欄なら取得しない)。実質的な制御フラグはこの列。
B31: 副TIMS起動引数 | C31: 文字列 | D31: 2本目のCSV取得時にTIMS_ClientPC.exeへ渡す引数 | E31: -site:"副拠点コード"
B32: 副CSVファイル名 | C32: 文字列 | D32: 2本目にTIMSからエクスポートするCSVファイル名 | E32: 外注鉄では倉庫在庫データ.csv
B33: 主CSV貼付開始セル | C33: セル番地 | D33: 主CSVをバーコード貼付シートへ貼り付ける開始セル | E33: 通常はA3、外注鉄はA4000
B34: 副CSV貼付開始セル | C34: セル番地 | D34: 副CSVをバーコード貼付シートへ貼り付ける開始セル | E34: 外注鉄はA3
B35: 副CSV範囲_終端行 | C35: 整数 | D35: 副CSVのコピー範囲終端行 | E35: 外注鉄では3953
A36: 欠品（色）シート構造 | B36: 欠品色_列挿入位置 | C36: 整数 | D36: 欠品（色）シートで新規列を挿入する位置 | E36: 外注鉄シナリオで確認
B37: 欠品色_コピペ元列 | C37: 列記号 | D37: 欠品（色）シートのコピー元列 | E37: 外注鉄ではAA
B38: 欠品色_コピペ先列 | C38: 列記号 | D38: 欠品（色）シートの貼り付け先列 | E38: 外注鉄ではZ
B39: 欠品色_処理開始行 | C39: 整数 | D39: 欠品（色）シートの処理開始行 | E39: 外注鉄では41
B40: 欠品色_処理終了行 | C40: 整数 | D40: 欠品（色）シートの処理終了行 | E40: 外注鉄では63
...

Sheet 要確認事項
A1: ステータス | B1: 対象拠点 | C1: 項目 | D1: 内容
A2: 決定済み(実装方針決定) | B2: 製造 | C2: OLDバックアップ_実行 | D2: 資料上、倉庫にはOLDフォルダ退避処理の記載があるが、製造の資料には同処理が確認できなかった。未実装か、確認漏れか。 【2026/7/6 シナリオPDF確認】製造在庫チェック-V1.0のPDFを確認。ファイルコピー(17行目)の直後はメモ「念のために起動しているTIMSを止める」(18行目)に進んでおり、倉庫・船舶にある「処理前(前日)分をOLDフォルダーにバックアップする」ブロック(V1)が存在しない。製造にはOLDバックアップ機能は未実装であることを確認(確認漏れではなく実装差)。統合版では製造のOLDバックアップ_実行フラグを「無」で確定。 【2026/7/6 天野決定】製造のOLDバックアップ機能は統合版で新規実装する（当初の「無」判定から方針変更）。残し方は、ファイル名末尾に「-YYYYMMDD」（処理実行日）を付与し、指定した保存フォルダに保存する方式に決定。
A3: 決定済み | B3: 製造 | C3: CSVコピペ貼付先 | D3: 製造版のCSV→バーコード貼付コピペで、貼付先が単一セルではなく範囲(A3:C1400)表記になっている。他拠点は単一セルA3。仕様差か記載の揺れか要確認。 【2026/7/6 シナリオPDF確認】製造在庫チェック-V1.0のPDF(93行目)を確認したが、画像の解像度上「単一セル A3」なのか「A3:C1400」の範囲指定なのか判別しきれず。他拠点(東京・福岡・倉庫・船舶)はいずれも単一セル(A3等)への「すべて」貼付で統一されている。実機で製造シナリオのこのステップを開いて設定内容を直接確認するのが確実。 【2026/7/6 製造在庫チェック-V1.0 PDF実物確認により確定】 欠品シート：本体範囲 AD37:AD47 → AC37（貼付形式：値）／末尾2行 AD38:AD39 → AC38（貼付形式：すべて） 在庫額シート：本体範囲 AA37:AA48 → Z37（貼付形式：値）／末尾2行 AA38:AA39 → Z38（貼付形式：すべて） 引継ぎメモの「本体範囲を値貼付＋末尾2行をすべて貼付」という2段階構造どおりであることを確認。単一セルではなく上記の通り単一セル貼付＋開始行37で他拠点と整合。
A4: 決定済み | B4: 倉庫/札幌 | C4: 商品別シートの列構成(D/E/O等) | D4: 発注点補正・O列転記の列構成は製造の実ファイルでのみ実データ確認済み。倉庫・札幌の商品別シート(1,2,3…)が同じ列構成か未確認。
A5: 決定済み(パターン確認) | B5: 全拠点 | C5: 欠品/在庫額_処理開始行・終了行 | D5: 現状は固定値。将来的に「最初の空行取得」等で動的化するか、固定値のまま設定表で管理するかの方針を確定させる必要がある。 【2026/7/6 シナリオPDF確認】6拠点分(成果連絡表・東京・福岡・船舶・倉庫・製造)のPDFを比較した結果、欠品/在庫額シートのコピペは全拠点で「本体範囲を値貼付」＋「末尾2行分をすべて貼付」という同一の2段階構造であることを確認。開始行のみ拠点ごとに異なる(東京27/福岡29/倉庫37/船舶24/製造37)。構造が共通なので、開始行・終了行を拠点別変数として管理する現行方針(拠点別設定値シート)のまま統合してよいと判断。
A6: 決定済み | B6: 全拠点 | C6: 発注点補正・O列転記の要否 | D6: 荘田室長への確認事項（別紙：報告確認書面）の回答を得て、フラグのデフォルト値を最終確定する。 【決定】2026/7/3 荘田室長より口頭確認：発注点0かつ在庫>0の場合、在庫数を発注点に書き換えるロジックは全拠点共通でよい。統合版は共通実装する。 【2026/7/15 荘田室長より書面(メール)で再確認・業務的背景を確認】発注点を割ったまま3ヶ月以上放置された品目は「在庫する意思がないもの」とみなし発注点を0に設定して管理対象から外す運用。その後まれに遅れて入庫するものがあり、これは「在庫する意思が残っていた」ものとして復活処置（入荷数＝発注点に書き換え）を行い、在庫管理サイクルに再度乗せる。7/3の口頭確認と同一結論であることを書面で再確認。 【2026/7/15 天野判断】発注点補正は9拠点共通の1本のロジック（行ループ内条件分岐、拠点別IF分岐なし）で実装するため、拠点ごとの実装有無という前提自体が旧・個別シナリオ時代のものであり汎用版には適用されない。拠点別設定値シートの発注点補正_実行列は全拠点「有」に統一し、仙台・福岡・東京・成果連絡表(色物)に付いていた「(要現物確認)」の注記は削除。個別拠点ごとの現物確認は不要と判断。
A7: 未確認 | B7: 外注鉄 | C7: 主・副CSVの位置づけ | D7: シナリオではZ3934の外注在庫データをA4000へ、Z3932の倉庫在庫データをA3へ貼り付けている。統合版でも外注鉄を主拠点として扱い、倉庫データを副データセットとして取り込む設計でよいか。
A8: 決定済み | B8: 外注鉄 | C8: 発注点補正_実行 | D8: 外注鉄PDFでは倉庫・製造で確認されたCOUNTIFによる発注点補正処理が明示されていない。未実装で正しいか、無効ブロック内に存在するか実物で要確認。 【決定】2026/7/3 荘田室長より口頭確認：発注点0かつ在庫>0の場合、在庫数を発注点に書き換えるロジックは全拠点共通でよい。統合版は共通実装する。 【2026/7/15 天野判断】発注点補正は全拠点共通の1本のロジックに統合されたため、外注鉄個別の実装有無確認は不要と判断（行6の全体決定を参照）。
A9: 決定済み | B9: 外注鉄 | C9: O列転記_実行 | D9: 外注鉄PDFではO列→E列転記処理を確認できない。外注鉄では不要という仕様か要確認。 【2026/7/6 荘田室長へメール確認中】塚田の想定回答：問題なし(外注鉄のO列差分はどのシートに書き加えても問題なく、各拠点共通処理化してよい)。正式回答が来るまでは暫定反映とし、拠点別設定値シートのO列転記_実行フラグを暫定「有」にする。 【2026/7/6 荘田室長 正式回答（想定通り）】問題なし、各拠点共通処理でよい。あわせて業務的な意味も判明：規定日数(多くは90日)を過ぎても在庫が動かない＝担当者に補充の意思がないとみなし、その差分値(O列)を発注点(E列)へ書き換えることで、結果的に発注点を引き下げる効果を持たせている。これは②の発注点リセット基準日数(部署別・シート単位の90日/365日等)と同じ「規定日数」概念を使っている可能性が高く、発注点0リセット機能とO列転記が同系統の仕組みである可能性がある。統合実装時に両者の関係を要整理。
A10: 一部確認済み | B10: 外注鉄 | C10: CSV終端行 | D10: PDF記載では倉庫CSVがA1:D3953、外注CSVがA1:D365。件数が固定上限か、その時点の実データ件数かを確認し、動的最終行取得へ変更するか判断する。 【一部確認済み】2026/7/3 実物PDF再確認により、外注CSVの終端行は365ではなく2365が正(変数表を修正済み)。固定上限か都度の実データ件数かは引き続き未確認。
A11: 未確認 | B11: 外注鉄 | C11: 色シートの共通化 | D11: 欠品（色）・在庫額（色）が外注鉄固有なのか、他拠点にも存在するが未処理なのかを確認する。
A12: 未確認 | B12: 外注鉄 | C12: 無効ブロックの内容 | D12: PDFでは行番号が108から151、160から189へ飛んでおり無効ブロックが折りたたまれている。休日判定・バックアップ・補正処理等が含まれていないか実シナリオで確認する。
... A57: 未着手（本番切替時タスク） | B57: 全拠点 | C57: 書き戻し前のバックアップドライブ退避処理の新規実装 | D57: 2026/7/14 天野確認：原本上書きへの不安があるため、書き戻し直前に前日ファイルをバックアップドライブへ退避する処理を新規に設ける想定。V1.0時代の「NAS上のOLDフォルダへ退避」方式(倉庫・船舶で実装済み、製造は要確認事項#2で新規実装決定済み)とは退避先の方式が異なるため、統合版のOLDバックアップ_実行フラグの意味・実装方式を「バックアップドライブ退避」に合わせて再設計する必要がある。

Sheet 発注点リセット_部署別設定
A1: 拠点コード | B1: 拠点名 | C1: シート名(部署) | D1: リセット日数 | E1: 基準数式(参考) | F1: 確認状況 | G1: 備考
A2: Z3951 | B2: 製造(大型) | C2: 1 | D2: 90 | E2: TODAY()-90日 相当 | F2: 確認済み | G2: 実ファイルで確認(2026/7/3)
A3: Z3951 | B3: 製造(大型) | C3: 2 | D3: 90 | E3: TODAY()-90日 相当 | F3: 確認済み | G3: 実ファイルで確認(2026/7/3)
A4: Z3951 | B4: 製造(大型) | C4: 3 | D4: 90 | E4: TODAY()-90日 相当 | F4: 確認済み | G4: 実ファイルで確認(2026/7/3)
A5: Z3951 | B5: 製造(大型) | C5: 4 | D5: 90 | E5: TODAY()-90日 相当 | F5: 確認済み | G5: 実ファイルで確認(2026/7/3)
A6: Z3951 | B6: 製造(大型) | C6: 5 | D6: 90 | E6: TODAY()-90日 相当 | F6: 確認済み | G6: 実ファイルで確認(2026/7/3)
A7: Z3951 | B7: 製造(大型) | C7: 6 | D7: 90 | E7: TODAY()-90日 相当 | F7: 確認済み | G7: 実ファイルで確認(2026/7/3)
A8: Z3951 | B8: 製造(大型) | C8: 7 | D8: 90 | E8: TODAY()-90日 相当 | F8: 確認済み | G8: 実ファイルで確認(2026/7/3)
A9: Z3951 | B9: 製造(大型) | C9: 8 | D9: 90 | E9: TODAY()-90日 相当 | F9: 確認済み | G9: 実ファイルで確認(2026/7/3)
A10: Z3951 | B10: 製造(大型) | C10: 9 | D10: 90 | E10: TODAY()-90日 相当 | F10: 確認済み | G10: 実ファイルで確認(2026/7/3)
A11: Z1915 | B11: 船舶(機械部) | C11: 1 | D11: 365 | E11: TODAY()-365日 相当 | F11: 確認済み | G11: 実ファイルで確認(2026/7/3)
A12: Z1915 | B12: 船舶(機械部) | C12: 2 | D12: 90 | E12: TODAY()-90日 相当 | F12: 確認済み | G12: 実ファイルで確認(2026/7/3)
A13: Z1915 | B13: 船舶(機械部) | C13: 3 | D13: 90 | E13: TODAY()-90日 相当 | F13: 確認済み | G13: 実ファイルで確認(2026/7/3)
... A139: Z1905 | B139: 東京 | C139: 19 | D139: 90 | E139: TODAY()-90日 相当 | F139: 確認済み(要確認) | G139: 実ファイルで確認(2026/7/3)。F1式自体は他部署と同じ=TODAY()-90で、データも正常に入っているが、RPAシナリオのループ回数は16回までのため、この部署(17〜19)はシナリオの処理対象外になっている可能性が高い。
A140: Z1907 | B140: 福岡 | C140: 1 | D140: 90 | E140: TODAY()-90日 相当
A141: Z1907 | B141: 福岡 | C141: 2 | D141: 90 | E141: TODAY()-90日 相当
A142: Z1907 | B142: 福岡 | C142: 3 | D142: 90 | E142: TODAY()-90日 相当
A143: Z1907 | B143: 福岡 | C143: 4 | D143: 90 | E143: TODAY()-90日 相当
A144: Z1907 | B144: 福岡 | C144: 5 | D144: 90 | E144: TODAY()-90日 相当
A145: Z1907 | B145: 福岡 | C145: 6 | D145: 90 | E145: TODAY()-90日 相当
A146: Z1907 | B146: 福岡 | C146: 7 | D146: 90 | E146: TODAY()-90日 相当
A147: Z1907 | B147: 福岡 | C147: 8 | D147: 90 | E147: TODAY()-90日 相当
A148: Z1907 | B148: 福岡 | C148: 9 | D148: 90 | E148: TODAY()-90日 相当
A149: Z1907 | B149: 福岡 | C149: 10 | D149: 90 | E149: TODAY()-90日 相当
A150: Z1907 | B150: 福岡 | C150: 11 | D150: 90 | E150: TODAY()-90日 相当
A151: Z1907 | B151: 福岡 | C151: 12 | D151: 90 | E151: TODAY()-90日 相当
... A176: Z3934 | B176: 成果連絡表(色物) | C176: 18 | D176: 90 | E176: TODAY()-90日 相当
